<mujoco model="yam_ball_sorting">
  <compiler angle="radian" meshdir="assets/i2rt_yam/assets" texturedir="."/>

  <option integrator="implicitfast"/>

  <visual>
    <global azimuth="120" elevation="-20" offwidth="1920" offheight="1080"/>
    <quality shadowsize="8192" offsamples="16"/>
    <headlight ambient="0.40 0.40 0.40" diffuse="0.0 0.0 0.0" specular="0 0 0"/>
    <rgba haze="1.0 1.0 1.0 1"/>
  </visual>

  <default>
    <default class="yam">
      <position inheritrange="1"/>
      <joint frictionloss="0.1" axis="0 0 1"/>
      <default class="dm4340">
        <joint armature="0.032"/>
        <position kp="40" kv="2.5" forcerange="-28 28"/>
      </default>
      <default class="dm4310">
        <joint armature="0.0018"/>
        <position kp="10" kv="1" forcerange="-10 10"/>
      </default>
      <default class="visual">
        <geom type="mesh" contype="0" conaffinity="0" density="0" group="2" material="black"/>
      </default>
      <default class="collision">
        <geom group="3" type="capsule" friction="2.0 0.1 0.01" condim="6"/>
        <default class="sphere_collision">
          <geom size="0.0006 0 0" type="sphere" rgba="1 0 0 1" friction="4.0 0.1 0.01" condim="6" solimp="0.998 0.998 0.001" solref="0.004 1" priority="2"/>
        </default>
      </default>
      <default class="finger">
        <joint type="slide" armature="0.1" frictionloss="0.1"/>
        <position ctrlrange="0.0 0.0495" kp="400" kv="14" inheritrange="0"/>
      </default>
    </default>
  </default>

  <asset>
    <material name="black" rgba="0.30 0.30 0.30 1"/>
    <material name="white" rgba="0.9 0.9 0.9 1"/>

    <mesh file="model2.stl"/>
    <mesh file="model2__2.stl"/>
    <mesh file="model2__3.stl"/>
    <mesh file="model2__4.stl"/>
    <mesh file="model2__5.stl"/>
    <mesh file="model2__6.stl"/>
    <mesh file="model2__7.stl"/>
    <mesh file="model2__8.stl"/>
    <mesh file="model2__9.stl"/>
    <mesh file="model2__10.stl"/>
    <mesh file="model2__11.stl"/>
    <mesh file="model2__12.stl"/>
    <mesh file="model2__13.stl"/>
    <mesh file="model2__14.stl"/>
    <mesh file="model2__15.stl"/>
    <mesh file="model2__16.stl"/>
    <mesh file="model2__17.stl"/>
    <mesh name="base_visual_gate" file="base_visual_gate.stl"/>
    <mesh name="camera_d405" file="d405.stl"/>

    <!-- Ball sorting toy -->
    <texture type="2d" name="ball-sorting-toy-texture" file="assets/ball_sorting_toy/texture.png"/>
    <material name="ball-sorting-toy-material" texture="ball-sorting-toy-texture" specular="0.2" shininess="0.2"/>
    <mesh name="ball-sorting-toy-model" file="../../ball_sorting_toy/model.obj" scale="0.113 0.113 0.113"/>
    <mesh name="ball-sorting-toy-collision-0" file="../../ball_sorting_toy/model/model_collision_0.obj" scale="0.113 0.113 0.113"/>
    <mesh name="ball-sorting-toy-collision-1" file="../../ball_sorting_toy/model/model_collision_1.obj" scale="0.113 0.113 0.113"/>
    <mesh name="ball-sorting-toy-collision-2" file="../../ball_sorting_toy/model/model_collision_2.obj" scale="0.113 0.113 0.113"/>
    <mesh name="ball-sorting-toy-collision-3" file="../../ball_sorting_toy/model/model_collision_3.obj" scale="0.113 0.113 0.113"/>
    <mesh name="ball-sorting-toy-collision-4" file="../../ball_sorting_toy/model/model_collision_4.obj" scale="0.113 0.113 0.113"/>
    <mesh name="ball-sorting-toy-collision-5" file="../../ball_sorting_toy/model/model_collision_5.obj" scale="0.113 0.113 0.113"/>
    <mesh name="ball-sorting-toy-collision-6" file="../../ball_sorting_toy/model/model_collision_6.obj" scale="0.113 0.113 0.113"/>
    <mesh name="ball-sorting-toy-collision-7" file="../../ball_sorting_toy/model/model_collision_7.obj" scale="0.113 0.113 0.113"/>
    <mesh name="ball-sorting-toy-collision-8" file="../../ball_sorting_toy/model/model_collision_8.obj" scale="0.113 0.113 0.113"/>
    <mesh name="ball-sorting-toy-collision-9" file="../../ball_sorting_toy/model/model_collision_9.obj" scale="0.113 0.113 0.113"/>
    <mesh name="ball-sorting-toy-collision-10" file="../../ball_sorting_toy/model/model_collision_10.obj" scale="0.113 0.113 0.113"/>
    <mesh name="ball-sorting-toy-collision-11" file="../../ball_sorting_toy/model/model_collision_11.obj" scale="0.113 0.113 0.113"/>
    <mesh name="ball-sorting-toy-collision-12" file="../../ball_sorting_toy/model/model_collision_12.obj" scale="0.113 0.113 0.113"/>
    <mesh name="ball-sorting-toy-collision-13" file="../../ball_sorting_toy/model/model_collision_13.obj" scale="0.113 0.113 0.113"/>
    <mesh name="ball-sorting-toy-collision-14" file="../../ball_sorting_toy/model/model_collision_14.obj" scale="0.113 0.113 0.113"/>
    <mesh name="ball-sorting-toy-collision-15" file="../../ball_sorting_toy/model/model_collision_15.obj" scale="0.113 0.113 0.113"/>
    <mesh name="ball-sorting-toy-collision-16" file="../../ball_sorting_toy/model/model_collision_16.obj" scale="0.113 0.113 0.113"/>
    <mesh name="ball-sorting-toy-collision-17" file="../../ball_sorting_toy/model/model_collision_17.obj" scale="0.113 0.113 0.113"/>
    <mesh name="ball-sorting-toy-collision-18" file="../../ball_sorting_toy/model/model_collision_18.obj" scale="0.113 0.113 0.113"/>
    <mesh name="ball-sorting-toy-collision-19" file="../../ball_sorting_toy/model/model_collision_19.obj" scale="0.113 0.113 0.113"/>
    <mesh name="ball-sorting-toy-collision-20" file="../../ball_sorting_toy/model/model_collision_20.obj" scale="0.113 0.113 0.113"/>
    <mesh name="ball-sorting-toy-collision-21" file="../../ball_sorting_toy/model/model_collision_21.obj" scale="0.113 0.113 0.113"/>
    <mesh name="ball-sorting-toy-collision-22" file="../../ball_sorting_toy/model/model_collision_22.obj" scale="0.113 0.113 0.113"/>
    <mesh name="ball-sorting-toy-collision-23" file="../../ball_sorting_toy/model/model_collision_23.obj" scale="0.113 0.113 0.113"/>
    <mesh name="ball-sorting-toy-collision-24" file="../../ball_sorting_toy/model/model_collision_24.obj" scale="0.113 0.113 0.113"/>
    <mesh name="ball-sorting-toy-collision-25" file="../../ball_sorting_toy/model/model_collision_25.obj" scale="0.113 0.113 0.113"/>
    <mesh name="ball-sorting-toy-collision-26" file="../../ball_sorting_toy/model/model_collision_26.obj" scale="0.113 0.113 0.113"/>
    <mesh name="ball-sorting-toy-collision-27" file="../../ball_sorting_toy/model/model_collision_27.obj" scale="0.113 0.113 0.113"/>
    <mesh name="ball-sorting-toy-collision-28" file="../../ball_sorting_toy/model/model_collision_28.obj" scale="0.113 0.113 0.113"/>
    <mesh name="ball-sorting-toy-collision-29" file="../../ball_sorting_toy/model/model_collision_29.obj" scale="0.113 0.113 0.113"/>
    <mesh name="ball-sorting-toy-collision-30" file="../../ball_sorting_toy/model/model_collision_30.obj" scale="0.113 0.113 0.113"/>
    <mesh name="ball-sorting-toy-collision-31" file="../../ball_sorting_toy/model/model_collision_31.obj" scale="0.113 0.113 0.113"/>
    <mesh name="ball-sorting-toy-collision-32" file="../../ball_sorting_toy/model/model_collision_32.obj" scale="0.113 0.113 0.113"/>
    <mesh name="ball-sorting-toy-collision-33" file="../../ball_sorting_toy/model/model_collision_33.obj" scale="0.113 0.113 0.113"/>
    <mesh name="ball-sorting-toy-collision-34" file="../../ball_sorting_toy/model/model_collision_34.obj" scale="0.113 0.113 0.113"/>
    <mesh name="ball-sorting-toy-collision-35" file="../../ball_sorting_toy/model/model_collision_35.obj" scale="0.113 0.113 0.113"/>
    <mesh name="ball-sorting-toy-collision-36" file="../../ball_sorting_toy/model/model_collision_36.obj" scale="0.113 0.113 0.113"/>
    <mesh name="ball-sorting-toy-collision-37" file="../../ball_sorting_toy/model/model_collision_37.obj" scale="0.113 0.113 0.113"/>
    <mesh name="ball-sorting-toy-collision-38" file="../../ball_sorting_toy/model/model_collision_38.obj" scale="0.113 0.113 0.113"/>
    <mesh name="ball-sorting-toy-collision-39" file="../../ball_sorting_toy/model/model_collision_39.obj" scale="0.113 0.113 0.113"/>
    <mesh name="ball-sorting-toy-collision-40" file="../../ball_sorting_toy/model/model_collision_40.obj" scale="0.113 0.113 0.113"/>
    <mesh name="ball-sorting-toy-collision-41" file="../../ball_sorting_toy/model/model_collision_41.obj" scale="0.113 0.113 0.113"/>
    <mesh name="ball-sorting-toy-collision-42" file="../../ball_sorting_toy/model/model_collision_42.obj" scale="0.113 0.113 0.113"/>
    <mesh name="ball-sorting-toy-collision-43" file="../../ball_sorting_toy/model/model_collision_43.obj" scale="0.113 0.113 0.113"/>
    <mesh name="ball-sorting-toy-collision-44" file="../../ball_sorting_toy/model/model_collision_44.obj" scale="0.113 0.113 0.113"/>
    <mesh name="ball-sorting-toy-collision-45" file="../../ball_sorting_toy/model/model_collision_45.obj" scale="0.113 0.113 0.113"/>
    <mesh name="ball-sorting-toy-collision-46" file="../../ball_sorting_toy/model/model_collision_46.obj" scale="0.113 0.113 0.113"/>
    <mesh name="ball-sorting-toy-collision-47" file="../../ball_sorting_toy/model/model_collision_47.obj" scale="0.113 0.113 0.113"/>
    <mesh name="ball-sorting-toy-collision-48" file="../../ball_sorting_toy/model/model_collision_48.obj" scale="0.113 0.113 0.113"/>
    <mesh name="ball-sorting-toy-collision-49" file="../../ball_sorting_toy/model/model_collision_49.obj" scale="0.113 0.113 0.113"/>
    <mesh name="ball-sorting-toy-collision-50" file="../../ball_sorting_toy/model/model_collision_50.obj" scale="0.113 0.113 0.113"/>
    <mesh name="ball-sorting-toy-collision-51" file="../../ball_sorting_toy/model/model_collision_51.obj" scale="0.113 0.113 0.113"/>
    <mesh name="ball-sorting-toy-collision-52" file="../../ball_sorting_toy/model/model_collision_52.obj" scale="0.113 0.113 0.113"/>
    <mesh name="ball-sorting-toy-collision-53" file="../../ball_sorting_toy/model/model_collision_53.obj" scale="0.113 0.113 0.113"/>
    <mesh name="ball-sorting-toy-collision-54" file="../../ball_sorting_toy/model/model_collision_54.obj" scale="0.113 0.113 0.113"/>
    <mesh name="ball-sorting-toy-collision-55" file="../../ball_sorting_toy/model/model_collision_55.obj" scale="0.113 0.113 0.113"/>
    <mesh name="ball-sorting-toy-collision-56" file="../../ball_sorting_toy/model/model_collision_56.obj" scale="0.113 0.113 0.113"/>
    <mesh name="ball-sorting-toy-collision-57" file="../../ball_sorting_toy/model/model_collision_57.obj" scale="0.113 0.113 0.113"/>
    <mesh name="ball-sorting-toy-collision-58" file="../../ball_sorting_toy/model/model_collision_58.obj" scale="0.113 0.113 0.113"/>
    <mesh name="ball-sorting-toy-collision-59" file="../../ball_sorting_toy/model/model_collision_59.obj" scale="0.113 0.113 0.113"/>
    <mesh name="ball-sorting-toy-collision-60" file="../../ball_sorting_toy/model/model_collision_60.obj" scale="0.113 0.113 0.113"/>
    <mesh name="ball-sorting-toy-collision-61" file="../../ball_sorting_toy/model/model_collision_61.obj" scale="0.113 0.113 0.113"/>
    <mesh name="ball-sorting-toy-collision-62" file="../../ball_sorting_toy/model/model_collision_62.obj" scale="0.113 0.113 0.113"/>
    <mesh name="ball-sorting-toy-collision-63" file="../../ball_sorting_toy/model/model_collision_63.obj" scale="0.113 0.113 0.113"/>
    <mesh name="ball-sorting-toy-collision-64" file="../../ball_sorting_toy/model/model_collision_64.obj" scale="0.113 0.113 0.113"/>
    <mesh name="ball-sorting-toy-collision-65" file="../../ball_sorting_toy/model/model_collision_65.obj" scale="0.113 0.113 0.113"/>
    <mesh name="ball-sorting-toy-collision-66" file="../../ball_sorting_toy/model/model_collision_66.obj" scale="0.113 0.113 0.113"/>
    <mesh name="ball-sorting-toy-collision-67" file="../../ball_sorting_toy/model/model_collision_67.obj" scale="0.113 0.113 0.113"/>
    <mesh name="ball-sorting-toy-collision-68" file="../../ball_sorting_toy/model/model_collision_68.obj" scale="0.113 0.113 0.113"/>
    <mesh name="ball-sorting-toy-collision-69" file="../../ball_sorting_toy/model/model_collision_69.obj" scale="0.113 0.113 0.113"/>
    <mesh name="ball-sorting-toy-collision-70" file="../../ball_sorting_toy/model/model_collision_70.obj" scale="0.113 0.113 0.113"/>
    <mesh name="ball-sorting-toy-collision-71" file="../../ball_sorting_toy/model/model_collision_71.obj" scale="0.113 0.113 0.113"/>
    <mesh name="ball-sorting-toy-collision-72" file="../../ball_sorting_toy/model/model_collision_72.obj" scale="0.113 0.113 0.113"/>
    <mesh name="ball-sorting-toy-collision-73" file="../../ball_sorting_toy/model/model_collision_73.obj" scale="0.113 0.113 0.113"/>
    <mesh name="ball-sorting-toy-collision-74" file="../../ball_sorting_toy/model/model_collision_74.obj" scale="0.113 0.113 0.113"/>
    <mesh name="ball-sorting-toy-collision-75" file="../../ball_sorting_toy/model/model_collision_75.obj" scale="0.113 0.113 0.113"/>
    <mesh name="ball-sorting-toy-collision-76" file="../../ball_sorting_toy/model/model_collision_76.obj" scale="0.113 0.113 0.113"/>
    <mesh name="ball-sorting-toy-collision-77" file="../../ball_sorting_toy/model/model_collision_77.obj" scale="0.113 0.113 0.113"/>
    <mesh name="ball-sorting-toy-collision-78" file="../../ball_sorting_toy/model/model_collision_78.obj" scale="0.113 0.113 0.113"/>
    <mesh name="ball-sorting-toy-collision-79" file="../../ball_sorting_toy/model/model_collision_79.obj" scale="0.113 0.113 0.113"/>
    <mesh name="ball-sorting-toy-collision-80" file="../../ball_sorting_toy/model/model_collision_80.obj" scale="0.113 0.113 0.113"/>
    <mesh name="ball-sorting-toy-collision-81" file="../../ball_sorting_toy/model/model_collision_81.obj" scale="0.113 0.113 0.113"/>
    <mesh name="ball-sorting-toy-collision-82" file="../../ball_sorting_toy/model/model_collision_82.obj" scale="0.113 0.113 0.113"/>
    <mesh name="ball-sorting-toy-collision-83" file="../../ball_sorting_toy/model/model_collision_83.obj" scale="0.113 0.113 0.113"/>
    <mesh name="ball-sorting-toy-collision-84" file="../../ball_sorting_toy/model/model_collision_84.obj" scale="0.113 0.113 0.113"/>
    <mesh name="ball-sorting-toy-collision-85" file="../../ball_sorting_toy/model/model_collision_85.obj" scale="0.113 0.113 0.113"/>
    <mesh name="ball-sorting-toy-collision-86" file="../../ball_sorting_toy/model/model_collision_86.obj" scale="0.113 0.113 0.113"/>
    <mesh name="ball-sorting-toy-collision-87" file="../../ball_sorting_toy/model/model_collision_87.obj" scale="0.113 0.113 0.113"/>
    <mesh name="ball-sorting-toy-collision-88" file="../../ball_sorting_toy/model/model_collision_88.obj" scale="0.113 0.113 0.113"/>
    <mesh name="ball-sorting-toy-collision-89" file="../../ball_sorting_toy/model/model_collision_89.obj" scale="0.113 0.113 0.113"/>
    <mesh name="ball-sorting-toy-collision-90" file="../../ball_sorting_toy/model/model_collision_90.obj" scale="0.113 0.113 0.113"/>
    <mesh name="ball-sorting-toy-collision-91" file="../../ball_sorting_toy/model/model_collision_91.obj" scale="0.113 0.113 0.113"/>
    <mesh name="ball-sorting-toy-collision-92" file="../../ball_sorting_toy/model/model_collision_92.obj" scale="0.113 0.113 0.113"/>
    <mesh name="ball-sorting-toy-collision-93" file="../../ball_sorting_toy/model/model_collision_93.obj" scale="0.113 0.113 0.113"/>
    <mesh name="ball-sorting-toy-collision-94" file="../../ball_sorting_toy/model/model_collision_94.obj" scale="0.113 0.113 0.113"/>
    <mesh name="ball-sorting-toy-collision-95" file="../../ball_sorting_toy/model/model_collision_95.obj" scale="0.113 0.113 0.113"/>
    <mesh name="ball-sorting-toy-collision-96" file="../../ball_sorting_toy/model/model_collision_96.obj" scale="0.113 0.113 0.113"/>
    <mesh name="ball-sorting-toy-collision-97" file="../../ball_sorting_toy/model/model_collision_97.obj" scale="0.113 0.113 0.113"/>
    <mesh name="ball-sorting-toy-collision-98" file="../../ball_sorting_toy/model/model_collision_98.obj" scale="0.113 0.113 0.113"/>
    <mesh name="ball-sorting-toy-collision-99" file="../../ball_sorting_toy/model/model_collision_99.obj" scale="0.113 0.113 0.113"/>
    <mesh name="ball-sorting-toy-collision-100" file="../../ball_sorting_toy/model/model_collision_100.obj" scale="0.113 0.113 0.113"/>
    <mesh name="ball-sorting-toy-collision-101" file="../../ball_sorting_toy/model/model_collision_101.obj" scale="0.113 0.113 0.113"/>
    <mesh name="ball-sorting-toy-collision-102" file="../../ball_sorting_toy/model/model_collision_102.obj" scale="0.113 0.113 0.113"/>
    <mesh name="ball-sorting-toy-collision-103" file="../../ball_sorting_toy/model/model_collision_103.obj" scale="0.113 0.113 0.113"/>
    <mesh name="ball-sorting-toy-collision-104" file="../../ball_sorting_toy/model/model_collision_104.obj" scale="0.113 0.113 0.113"/>
    <mesh name="ball-sorting-toy-collision-105" file="../../ball_sorting_toy/model/model_collision_105.obj" scale="0.113 0.113 0.113"/>
    <mesh name="ball-sorting-toy-collision-106" file="../../ball_sorting_toy/model/model_collision_106.obj" scale="0.113 0.113 0.113"/>
    <mesh name="ball-sorting-toy-collision-107" file="../../ball_sorting_toy/model/model_collision_107.obj" scale="0.113 0.113 0.113"/>
    <mesh name="ball-sorting-toy-collision-108" file="../../ball_sorting_toy/model/model_collision_108.obj" scale="0.113 0.113 0.113"/>
    <mesh name="ball-sorting-toy-collision-109" file="../../ball_sorting_toy/model/model_collision_109.obj" scale="0.113 0.113 0.113"/>
    <mesh name="ball-sorting-toy-collision-110" file="../../ball_sorting_toy/model/model_collision_110.obj" scale="0.113 0.113 0.113"/>
    <mesh name="ball-sorting-toy-collision-111" file="../../ball_sorting_toy/model/model_collision_111.obj" scale="0.113 0.113 0.113"/>
    <mesh name="ball-sorting-toy-collision-112" file="../../ball_sorting_toy/model/model_collision_112.obj" scale="0.113 0.113 0.113"/>
    <mesh name="ball-sorting-toy-collision-113" file="../../ball_sorting_toy/model/model_collision_113.obj" scale="0.113 0.113 0.113"/>
    <mesh name="ball-sorting-toy-collision-114" file="../../ball_sorting_toy/model/model_collision_114.obj" scale="0.113 0.113 0.113"/>
    <mesh name="ball-sorting-toy-collision-115" file="../../ball_sorting_toy/model/model_collision_115.obj" scale="0.113 0.113 0.113"/>
    <mesh name="ball-sorting-toy-collision-116" file="../../ball_sorting_toy/model/model_collision_116.obj" scale="0.113 0.113 0.113"/>
    <mesh name="ball-sorting-toy-collision-117" file="../../ball_sorting_toy/model/model_collision_117.obj" scale="0.113 0.113 0.113"/>
    <mesh name="ball-sorting-toy-collision-118" file="../../ball_sorting_toy/model/model_collision_118.obj" scale="0.113 0.113 0.113"/>
    <mesh name="ball-sorting-toy-collision-119" file="../../ball_sorting_toy/model/model_collision_119.obj" scale="0.113 0.113 0.113"/>
    <mesh name="ball-sorting-toy-collision-120" file="../../ball_sorting_toy/model/model_collision_120.obj" scale="0.113 0.113 0.113"/>
    <mesh name="ball-sorting-toy-collision-121" file="../../ball_sorting_toy/model/model_collision_121.obj" scale="0.113 0.113 0.113"/>
    <mesh name="ball-sorting-toy-collision-122" file="../../ball_sorting_toy/model/model_collision_122.obj" scale="0.113 0.113 0.113"/>
    <mesh name="ball-sorting-toy-collision-123" file="../../ball_sorting_toy/model/model_collision_123.obj" scale="0.113 0.113 0.113"/>
    <mesh name="ball-sorting-toy-collision-124" file="../../ball_sorting_toy/model/model_collision_124.obj" scale="0.113 0.113 0.113"/>
    <mesh name="ball-sorting-toy-collision-125" file="../../ball_sorting_toy/model/model_collision_125.obj" scale="0.113 0.113 0.113"/>
    <mesh name="ball-sorting-toy-collision-126" file="../../ball_sorting_toy/model/model_collision_126.obj" scale="0.113 0.113 0.113"/>
    <mesh name="ball-sorting-toy-collision-127" file="../../ball_sorting_toy/model/model_collision_127.obj" scale="0.113 0.113 0.113"/>
    <mesh name="ball-sorting-toy-collision-128" file="../../ball_sorting_toy/model/model_collision_128.obj" scale="0.113 0.113 0.113"/>
    <mesh name="ball-sorting-toy-collision-129" file="../../ball_sorting_toy/model/model_collision_129.obj" scale="0.113 0.113 0.113"/>
    <mesh name="ball-sorting-toy-collision-130" file="../../ball_sorting_toy/model/model_collision_130.obj" scale="0.113 0.113 0.113"/>
    <mesh name="ball-sorting-toy-collision-131" file="../../ball_sorting_toy/model/model_collision_131.obj" scale="0.113 0.113 0.113"/>
    <mesh name="ball-sorting-toy-collision-132" file="../../ball_sorting_toy/model/model_collision_132.obj" scale="0.113 0.113 0.113"/>
    <mesh name="ball-sorting-toy-collision-133" file="../../ball_sorting_toy/model/model_collision_133.obj" scale="0.113 0.113 0.113"/>
    <mesh name="ball-sorting-toy-collision-134" file="../../ball_sorting_toy/model/model_collision_134.obj" scale="0.113 0.113 0.113"/>
    <mesh name="ball-sorting-toy-collision-135" file="../../ball_sorting_toy/model/model_collision_135.obj" scale="0.113 0.113 0.113"/>
    <mesh name="ball-sorting-toy-collision-136" file="../../ball_sorting_toy/model/model_collision_136.obj" scale="0.113 0.113 0.113"/>
    <mesh name="ball-sorting-toy-collision-137" file="../../ball_sorting_toy/model/model_collision_137.obj" scale="0.113 0.113 0.113"/>
    <mesh name="ball-sorting-toy-collision-138" file="../../ball_sorting_toy/model/model_collision_138.obj" scale="0.113 0.113 0.113"/>
    <mesh name="ball-sorting-toy-collision-139" file="../../ball_sorting_toy/model/model_collision_139.obj" scale="0.113 0.113 0.113"/>
    <mesh name="ball-sorting-toy-collision-140" file="../../ball_sorting_toy/model/model_collision_140.obj" scale="0.113 0.113 0.113"/>
    <mesh name="ball-sorting-toy-collision-141" file="../../ball_sorting_toy/model/model_collision_141.obj" scale="0.113 0.113 0.113"/>
    <mesh name="ball-sorting-toy-collision-142" file="../../ball_sorting_toy/model/model_collision_142.obj" scale="0.113 0.113 0.113"/>
    <mesh name="ball-sorting-toy-collision-143" file="../../ball_sorting_toy/model/model_collision_143.obj" scale="0.113 0.113 0.113"/>
    <mesh name="ball-sorting-toy-collision-144" file="../../ball_sorting_toy/model/model_collision_144.obj" scale="0.113 0.113 0.113"/>
    <mesh name="ball-sorting-toy-collision-145" file="../../ball_sorting_toy/model/model_collision_145.obj" scale="0.113 0.113 0.113"/>
    <mesh name="ball-sorting-toy-collision-146" file="../../ball_sorting_toy/model/model_collision_146.obj" scale="0.113 0.113 0.113"/>
    <mesh name="ball-sorting-toy-collision-147" file="../../ball_sorting_toy/model/model_collision_147.obj" scale="0.113 0.113 0.113"/>
    <mesh name="ball-sorting-toy-collision-148" file="../../ball_sorting_toy/model/model_collision_148.obj" scale="0.113 0.113 0.113"/>
    <mesh name="ball-sorting-toy-collision-149" file="../../ball_sorting_toy/model/model_collision_149.obj" scale="0.113 0.113 0.113"/>
    <mesh name="ball-sorting-toy-collision-150" file="../../ball_sorting_toy/model/model_collision_150.obj" scale="0.113 0.113 0.113"/>
    <mesh name="ball-sorting-toy-collision-151" file="../../ball_sorting_toy/model/model_collision_151.obj" scale="0.113 0.113 0.113"/>
    <mesh name="ball-sorting-toy-collision-152" file="../../ball_sorting_toy/model/model_collision_152.obj" scale="0.113 0.113 0.113"/>
    <mesh name="ball-sorting-toy-collision-153" file="../../ball_sorting_toy/model/model_collision_153.obj" scale="0.113 0.113 0.113"/>
    <mesh name="ball-sorting-toy-collision-154" file="../../ball_sorting_toy/model/model_collision_154.obj" scale="0.113 0.113 0.113"/>
    <mesh name="ball-sorting-toy-collision-155" file="../../ball_sorting_toy/model/model_collision_155.obj" scale="0.113 0.113 0.113"/>
    <mesh name="ball-sorting-toy-collision-156" file="../../ball_sorting_toy/model/model_collision_156.obj" scale="0.113 0.113 0.113"/>
    <mesh name="ball-sorting-toy-collision-157" file="../../ball_sorting_toy/model/model_collision_157.obj" scale="0.113 0.113 0.113"/>
    <mesh name="ball-sorting-toy-collision-158" file="../../ball_sorting_toy/model/model_collision_158.obj" scale="0.113 0.113 0.113"/>
    <mesh name="ball-sorting-toy-collision-159" file="../../ball_sorting_toy/model/model_collision_159.obj" scale="0.113 0.113 0.113"/>
    <mesh name="ball-sorting-toy-collision-160" file="../../ball_sorting_toy/model/model_collision_160.obj" scale="0.113 0.113 0.113"/>
    <mesh name="ball-sorting-toy-collision-161" file="../../ball_sorting_toy/model/model_collision_161.obj" scale="0.113 0.113 0.113"/>
    <mesh name="ball-sorting-toy-collision-162" file="../../ball_sorting_toy/model/model_collision_162.obj" scale="0.113 0.113 0.113"/>
    <mesh name="ball-sorting-toy-collision-163" file="../../ball_sorting_toy/model/model_collision_163.obj" scale="0.113 0.113 0.113"/>
    <mesh name="ball-sorting-toy-collision-164" file="../../ball_sorting_toy/model/model_collision_164.obj" scale="0.113 0.113 0.113"/>
    <mesh name="ball-sorting-toy-collision-165" file="../../ball_sorting_toy/model/model_collision_165.obj" scale="0.113 0.113 0.113"/>
    <mesh name="ball-sorting-toy-collision-166" file="../../ball_sorting_toy/model/model_collision_166.obj" scale="0.113 0.113 0.113"/>
    <mesh name="ball-sorting-toy-collision-167" file="../../ball_sorting_toy/model/model_collision_167.obj" scale="0.113 0.113 0.113"/>
    <mesh name="ball-sorting-toy-collision-168" file="../../ball_sorting_toy/model/model_collision_168.obj" scale="0.113 0.113 0.113"/>
    <mesh name="ball-sorting-toy-collision-169" file="../../ball_sorting_toy/model/model_collision_169.obj" scale="0.113 0.113 0.113"/>
    <mesh name="ball-sorting-toy-collision-170" file="../../ball_sorting_toy/model/model_collision_170.obj" scale="0.113 0.113 0.113"/>
    <mesh name="ball-sorting-toy-collision-171" file="../../ball_sorting_toy/model/model_collision_171.obj" scale="0.113 0.113 0.113"/>
    <mesh name="ball-sorting-toy-collision-172" file="../../ball_sorting_toy/model/model_collision_172.obj" scale="0.113 0.113 0.113"/>
    <mesh name="ball-sorting-toy-collision-173" file="../../ball_sorting_toy/model/model_collision_173.obj" scale="0.113 0.113 0.113"/>
    <mesh name="ball-sorting-toy-collision-174" file="../../ball_sorting_toy/model/model_collision_174.obj" scale="0.113 0.113 0.113"/>
    <mesh name="ball-sorting-toy-collision-175" file="../../ball_sorting_toy/model/model_collision_175.obj" scale="0.113 0.113 0.113"/>
    <mesh name="ball-sorting-toy-collision-176" file="../../ball_sorting_toy/model/model_collision_176.obj" scale="0.113 0.113 0.113"/>
    <mesh name="ball-sorting-toy-collision-177" file="../../ball_sorting_toy/model/model_collision_177.obj" scale="0.113 0.113 0.113"/>
    <mesh name="ball-sorting-toy-collision-178" file="../../ball_sorting_toy/model/model_collision_178.obj" scale="0.113 0.113 0.113"/>
    <mesh name="ball-sorting-toy-collision-179" file="../../ball_sorting_toy/model/model_collision_179.obj" scale="0.113 0.113 0.113"/>
    <mesh name="ball-sorting-toy-collision-180" file="../../ball_sorting_toy/model/model_collision_180.obj" scale="0.113 0.113 0.113"/>
    <mesh name="ball-sorting-toy-collision-181" file="../../ball_sorting_toy/model/model_collision_181.obj" scale="0.113 0.113 0.113"/>
    <mesh name="ball-sorting-toy-collision-182" file="../../ball_sorting_toy/model/model_collision_182.obj" scale="0.113 0.113 0.113"/>
    <mesh name="ball-sorting-toy-collision-183" file="../../ball_sorting_toy/model/model_collision_183.obj" scale="0.113 0.113 0.113"/>
    <mesh name="ball-sorting-toy-collision-184" file="../../ball_sorting_toy/model/model_collision_184.obj" scale="0.113 0.113 0.113"/>
    <mesh name="ball-sorting-toy-collision-185" file="../../ball_sorting_toy/model/model_collision_185.obj" scale="0.113 0.113 0.113"/>
    <mesh name="ball-sorting-toy-collision-186" file="../../ball_sorting_toy/model/model_collision_186.obj" scale="0.113 0.113 0.113"/>
    <mesh name="ball-sorting-toy-collision-187" file="../../ball_sorting_toy/model/model_collision_187.obj" scale="0.113 0.113 0.113"/>
    <mesh name="ball-sorting-toy-collision-188" file="../../ball_sorting_toy/model/model_collision_188.obj" scale="0.113 0.113 0.113"/>
    <mesh name="ball-sorting-toy-collision-189" file="../../ball_sorting_toy/model/model_collision_189.obj" scale="0.113 0.113 0.113"/>
    <mesh name="ball-sorting-toy-collision-190" file="../../ball_sorting_toy/model/model_collision_190.obj" scale="0.113 0.113 0.113"/>
    <mesh name="ball-sorting-toy-collision-191" file="../../ball_sorting_toy/model/model_collision_191.obj" scale="0.113 0.113 0.113"/>
    <mesh name="ball-sorting-toy-collision-192" file="../../ball_sorting_toy/model/model_collision_192.obj" scale="0.113 0.113 0.113"/>
    <mesh name="ball-sorting-toy-collision-193" file="../../ball_sorting_toy/model/model_collision_193.obj" scale="0.113 0.113 0.113"/>
    <mesh name="ball-sorting-toy-collision-194" file="../../ball_sorting_toy/model/model_collision_194.obj" scale="0.113 0.113 0.113"/>
    <mesh name="ball-sorting-toy-collision-195" file="../../ball_sorting_toy/model/model_collision_195.obj" scale="0.113 0.113 0.113"/>
    <mesh name="ball-sorting-toy-collision-196" file="../../ball_sorting_toy/model/model_collision_196.obj" scale="0.113 0.113 0.113"/>
    <mesh name="ball-sorting-toy-collision-197" file="../../ball_sorting_toy/model/model_collision_197.obj" scale="0.113 0.113 0.113"/>
    <mesh name="ball-sorting-toy-collision-198" file="../../ball_sorting_toy/model/model_collision_198.obj" scale="0.113 0.113 0.113"/>
    <mesh name="ball-sorting-toy-collision-199" file="../../ball_sorting_toy/model/model_collision_199.obj" scale="0.113 0.113 0.113"/>
    <mesh name="ball-sorting-toy-collision-200" file="../../ball_sorting_toy/model/model_collision_200.obj" scale="0.113 0.113 0.113"/>
    <mesh name="ball-sorting-toy-collision-201" file="../../ball_sorting_toy/model/model_collision_201.obj" scale="0.113 0.113 0.113"/>
    <mesh name="ball-sorting-toy-collision-202" file="../../ball_sorting_toy/model/model_collision_202.obj" scale="0.113 0.113 0.113"/>
    <mesh name="ball-sorting-toy-collision-203" file="../../ball_sorting_toy/model/model_collision_203.obj" scale="0.113 0.113 0.113"/>
    <mesh name="ball-sorting-toy-collision-204" file="../../ball_sorting_toy/model/model_collision_204.obj" scale="0.113 0.113 0.113"/>
    <mesh name="ball-sorting-toy-collision-205" file="../../ball_sorting_toy/model/model_collision_205.obj" scale="0.113 0.113 0.113"/>
    <mesh name="ball-sorting-toy-collision-206" file="../../ball_sorting_toy/model/model_collision_206.obj" scale="0.113 0.113 0.113"/>
    <mesh name="ball-sorting-toy-collision-207" file="../../ball_sorting_toy/model/model_collision_207.obj" scale="0.113 0.113 0.113"/>
    <mesh name="ball-sorting-toy-collision-208" file="../../ball_sorting_toy/model/model_collision_208.obj" scale="0.113 0.113 0.113"/>
    <mesh name="ball-sorting-toy-collision-209" file="../../ball_sorting_toy/model/model_collision_209.obj" scale="0.113 0.113 0.113"/>
    <mesh name="ball-sorting-toy-collision-210" file="../../ball_sorting_toy/model/model_collision_210.obj" scale="0.113 0.113 0.113"/>
    <mesh name="ball-sorting-toy-collision-211" file="../../ball_sorting_toy/model/model_collision_211.obj" scale="0.113 0.113 0.113"/>
    <mesh name="ball-sorting-toy-collision-212" file="../../ball_sorting_toy/model/model_collision_212.obj" scale="0.113 0.113 0.113"/>
    <mesh name="ball-sorting-toy-collision-213" file="../../ball_sorting_toy/model/model_collision_213.obj" scale="0.113 0.113 0.113"/>
    <mesh name="ball-sorting-toy-collision-214" file="../../ball_sorting_toy/model/model_collision_214.obj" scale="0.113 0.113 0.113"/>
    <mesh name="ball-sorting-toy-collision-215" file="../../ball_sorting_toy/model/model_collision_215.obj" scale="0.113 0.113 0.113"/>
    <mesh name="ball-sorting-toy-collision-216" file="../../ball_sorting_toy/model/model_collision_216.obj" scale="0.113 0.113 0.113"/>
    <mesh name="ball-sorting-toy-collision-217" file="../../ball_sorting_toy/model/model_collision_217.obj" scale="0.113 0.113 0.113"/>
    <mesh name="ball-sorting-toy-collision-218" file="../../ball_sorting_toy/model/model_collision_218.obj" scale="0.113 0.113 0.113"/>
    <mesh name="ball-sorting-toy-collision-219" file="../../ball_sorting_toy/model/model_collision_219.obj" scale="0.113 0.113 0.113"/>
    <mesh name="ball-sorting-toy-collision-220" file="../../ball_sorting_toy/model/model_collision_220.obj" scale="0.113 0.113 0.113"/>
    <mesh name="ball-sorting-toy-collision-221" file="../../ball_sorting_toy/model/model_collision_221.obj" scale="0.113 0.113 0.113"/>
    <mesh name="ball-sorting-toy-collision-222" file="../../ball_sorting_toy/model/model_collision_222.obj" scale="0.113 0.113 0.113"/>
    <mesh name="ball-sorting-toy-collision-223" file="../../ball_sorting_toy/model/model_collision_223.obj" scale="0.113 0.113 0.113"/>
    <mesh name="ball-sorting-toy-collision-224" file="../../ball_sorting_toy/model/model_collision_224.obj" scale="0.113 0.113 0.113"/>
    <mesh name="ball-sorting-toy-collision-225" file="../../ball_sorting_toy/model/model_collision_225.obj" scale="0.113 0.113 0.113"/>
    <mesh name="ball-sorting-toy-collision-226" file="../../ball_sorting_toy/model/model_collision_226.obj" scale="0.113 0.113 0.113"/>
    <mesh name="ball-sorting-toy-collision-227" file="../../ball_sorting_toy/model/model_collision_227.obj" scale="0.113 0.113 0.113"/>
    <mesh name="ball-sorting-toy-collision-228" file="../../ball_sorting_toy/model/model_collision_228.obj" scale="0.113 0.113 0.113"/>
    <mesh name="ball-sorting-toy-collision-229" file="../../ball_sorting_toy/model/model_collision_229.obj" scale="0.113 0.113 0.113"/>
    <mesh name="ball-sorting-toy-collision-230" file="../../ball_sorting_toy/model/model_collision_230.obj" scale="0.113 0.113 0.113"/>
    <mesh name="ball-sorting-toy-collision-231" file="../../ball_sorting_toy/model/model_collision_231.obj" scale="0.113 0.113 0.113"/>
    <mesh name="ball-sorting-toy-collision-232" file="../../ball_sorting_toy/model/model_collision_232.obj" scale="0.113 0.113 0.113"/>
    <mesh name="ball-sorting-toy-collision-233" file="../../ball_sorting_toy/model/model_collision_233.obj" scale="0.113 0.113 0.113"/>
    <mesh name="ball-sorting-toy-collision-234" file="../../ball_sorting_toy/model/model_collision_234.obj" scale="0.113 0.113 0.113"/>
    <mesh name="ball-sorting-toy-collision-235" file="../../ball_sorting_toy/model/model_collision_235.obj" scale="0.113 0.113 0.113"/>
    <mesh name="ball-sorting-toy-collision-236" file="../../ball_sorting_toy/model/model_collision_236.obj" scale="0.113 0.113 0.113"/>
    <mesh name="ball-sorting-toy-collision-237" file="../../ball_sorting_toy/model/model_collision_237.obj" scale="0.113 0.113 0.113"/>
    <mesh name="ball-sorting-toy-collision-238" file="../../ball_sorting_toy/model/model_collision_238.obj" scale="0.113 0.113 0.113"/>
    <mesh name="ball-sorting-toy-collision-239" file="../../ball_sorting_toy/model/model_collision_239.obj" scale="0.113 0.113 0.113"/>
    <mesh name="ball-sorting-toy-collision-240" file="../../ball_sorting_toy/model/model_collision_240.obj" scale="0.113 0.113 0.113"/>
    <mesh name="ball-sorting-toy-collision-241" file="../../ball_sorting_toy/model/model_collision_241.obj" scale="0.113 0.113 0.113"/>
    <mesh name="ball-sorting-toy-collision-242" file="../../ball_sorting_toy/model/model_collision_242.obj" scale="0.113 0.113 0.113"/>
    <mesh name="ball-sorting-toy-collision-243" file="../../ball_sorting_toy/model/model_collision_243.obj" scale="0.113 0.113 0.113"/>
    <mesh name="ball-sorting-toy-collision-244" file="../../ball_sorting_toy/model/model_collision_244.obj" scale="0.113 0.113 0.113"/>
    <mesh name="ball-sorting-toy-collision-245" file="../../ball_sorting_toy/model/model_collision_245.obj" scale="0.113 0.113 0.113"/>
    <mesh name="ball-sorting-toy-collision-246" file="../../ball_sorting_toy/model/model_collision_246.obj" scale="0.113 0.113 0.113"/>
    <mesh name="ball-sorting-toy-collision-247" file="../../ball_sorting_toy/model/model_collision_247.obj" scale="0.113 0.113 0.113"/>
    <mesh name="ball-sorting-toy-collision-248" file="../../ball_sorting_toy/model/model_collision_248.obj" scale="0.113 0.113 0.113"/>
    <mesh name="ball-sorting-toy-collision-249" file="../../ball_sorting_toy/model/model_collision_249.obj" scale="0.113 0.113 0.113"/>
    <mesh name="ball-sorting-toy-collision-250" file="../../ball_sorting_toy/model/model_collision_250.obj" scale="0.113 0.113 0.113"/>
    <mesh name="ball-sorting-toy-collision-251" file="../../ball_sorting_toy/model/model_collision_251.obj" scale="0.113 0.113 0.113"/>
    <mesh name="ball-sorting-toy-collision-252" file="../../ball_sorting_toy/model/model_collision_252.obj" scale="0.113 0.113 0.113"/>
    <mesh name="ball-sorting-toy-collision-253" file="../../ball_sorting_toy/model/model_collision_253.obj" scale="0.113 0.113 0.113"/>
    <mesh name="ball-sorting-toy-collision-254" file="../../ball_sorting_toy/model/model_collision_254.obj" scale="0.113 0.113 0.113"/>
    <mesh name="ball-sorting-toy-collision-255" file="../../ball_sorting_toy/model/model_collision_255.obj" scale="0.113 0.113 0.113"/>
    <mesh name="ball-sorting-toy-collision-256" file="../../ball_sorting_toy/model/model_collision_256.obj" scale="0.113 0.113 0.113"/>
    <mesh name="ball-sorting-toy-collision-257" file="../../ball_sorting_toy/model/model_collision_257.obj" scale="0.113 0.113 0.113"/>
    <mesh name="ball-sorting-toy-collision-258" file="../../ball_sorting_toy/model/model_collision_258.obj" scale="0.113 0.113 0.113"/>
    <mesh name="ball-sorting-toy-collision-259" file="../../ball_sorting_toy/model/model_collision_259.obj" scale="0.113 0.113 0.113"/>
    <mesh name="ball-sorting-toy-collision-260" file="../../ball_sorting_toy/model/model_collision_260.obj" scale="0.113 0.113 0.113"/>
    <mesh name="ball-sorting-toy-collision-261" file="../../ball_sorting_toy/model/model_collision_261.obj" scale="0.113 0.113 0.113"/>
    <mesh name="ball-sorting-toy-collision-262" file="../../ball_sorting_toy/model/model_collision_262.obj" scale="0.113 0.113 0.113"/>
    <mesh name="ball-sorting-toy-collision-263" file="../../ball_sorting_toy/model/model_collision_263.obj" scale="0.113 0.113 0.113"/>
    <mesh name="ball-sorting-toy-collision-264" file="../../ball_sorting_toy/model/model_collision_264.obj" scale="0.113 0.113 0.113"/>
    <mesh name="ball-sorting-toy-collision-265" file="../../ball_sorting_toy/model/model_collision_265.obj" scale="0.113 0.113 0.113"/>
    <mesh name="ball-sorting-toy-collision-266" file="../../ball_sorting_toy/model/model_collision_266.obj" scale="0.113 0.113 0.113"/>
    <mesh name="ball-sorting-toy-collision-267" file="../../ball_sorting_toy/model/model_collision_267.obj" scale="0.113 0.113 0.113"/>
    <mesh name="ball-sorting-toy-collision-268" file="../../ball_sorting_toy/model/model_collision_268.obj" scale="0.113 0.113 0.113"/>
    <mesh name="ball-sorting-toy-collision-269" file="../../ball_sorting_toy/model/model_collision_269.obj" scale="0.113 0.113 0.113"/>
    <mesh name="ball-sorting-toy-collision-270" file="../../ball_sorting_toy/model/model_collision_270.obj" scale="0.113 0.113 0.113"/>
    <mesh name="ball-sorting-toy-collision-271" file="../../ball_sorting_toy/model/model_collision_271.obj" scale="0.113 0.113 0.113"/>
    <mesh name="ball-sorting-toy-collision-272" file="../../ball_sorting_toy/model/model_collision_272.obj" scale="0.113 0.113 0.113"/>
    <mesh name="ball-sorting-toy-collision-273" file="../../ball_sorting_toy/model/model_collision_273.obj" scale="0.113 0.113 0.113"/>
    <mesh name="ball-sorting-toy-collision-274" file="../../ball_sorting_toy/model/model_collision_274.obj" scale="0.113 0.113 0.113"/>
    <mesh name="ball-sorting-toy-collision-275" file="../../ball_sorting_toy/model/model_collision_275.obj" scale="0.113 0.113 0.113"/>
    <mesh name="ball-sorting-toy-collision-276" file="../../ball_sorting_toy/model/model_collision_276.obj" scale="0.113 0.113 0.113"/>
    <mesh name="ball-sorting-toy-collision-277" file="../../ball_sorting_toy/model/model_collision_277.obj" scale="0.113 0.113 0.113"/>

    <texture type="skybox" builtin="gradient" rgb1="1.0 1.0 1.0" rgb2="0.98 0.98 0.98" width="512" height="3072"/>
    <texture type="2d" name="groundplane" builtin="checker" mark="edge"
      rgb1="0.55 0.55 0.55" rgb2="0.50 0.50 0.50" markrgb="0.6 0.6 0.6" width="300" height="300"/>
    <material name="groundplane" texture="groundplane" texuniform="true" texrepeat="5 5" reflectance="0.2"/>
  </asset>

  <worldbody>
    <!-- Lighting -->
    <light pos="0 0 1.5" dir="0 0 -1" directional="true"
      diffuse="0.30 0.30 0.30" specular="0.05 0.05 0.05"/>

    <!-- Floor -->
    <geom name="floor" size="0 0 0.05" type="plane" rgba="0.75 0.75 0.75 1"/>

    <!-- Gate/station structure (visual) -->
    <geom type="mesh" contype="0" conaffinity="0" group="2" density="0" rgba="0.60 0.62 0.68 1" mesh="base_visual_gate"/>
    <geom size="0.2975 0.65 0.375" pos="0 0 0.375" type="box" group="3" rgba="1 0 0 0.0"/>

    <!-- Gate collision bodies + top camera -->
    <body name="gate_collision" pos="0 0 0.75">
      <geom size="0.015 0.015 0.45" pos="0 0.575 0.45" type="box" group="3" rgba="1 0 0 0.0"/>
      <geom size="0.015 0.015 0.45" pos="0 -0.575 0.45" type="box" group="3" rgba="1 0 0 0.0"/>
      <geom size="0.015 0.015 0.59" pos="0 0 0.915" quat="0.707107 0.707107 0 0" type="box" group="3" rgba="1 0 0 0.0"/>
      <body name="top_bar_center" pos="0 0 0.915">
        <body name="top_camera_d405" pos="0.08600512 -0.009 0.03932053" quat="0.183012 0.683013 0.683013 0.183012">
          <geom type="mesh" contype="0" conaffinity="0" group="2" density="0.001" mass="0.001"
            rgba="0 0 0 0" mesh="camera_d405"/>
          <body name="top_camera_frame" pos="0.009 0 0" quat="0 0 0 1">
            <camera name="top" pos="0 0 0" quat="0 1 0 0" fovy="58"/>
          </body>
        </body>
      </body>
    </body>

    <!-- Enclosure walls -->
    <geom name="back_wall" type="box" size="0.005 0.65 1.0"
      pos="0.9 0 1.0" group="2"
      rgba="0.88 0.88 0.88 1"/>
    <geom name="left_wall" type="box" size="0.45 0.005 1.0"
      pos="0.45 0.65 1.0" group="2"
      rgba="0.88 0.88 0.88 1"/>
    <geom name="right_wall" type="box" size="0.45 0.005 1.0"
      pos="0.45 -0.65 1.0" group="2"
      rgba="0.88 0.88 0.88 1"/>

    <!-- Play table (visual only + collision plane at surface) -->
    
    <!-- Side cameras on cage walls -->
    
    <!-- Overhead camera -->
    <body name="overhead_camera" pos="0.55 0.0 1.6">
      <camera name="overhead" pos="0 0 0" quat="0.707 0 0 -0.707" fovy="60"/>
    </body>

    <body name="left_side_camera" pos="0.5 0.55 1.05" euler="-1.3 0 3.14159">
      <camera name="left_side" pos="0 0 0" fovy="70"/>
    </body>
    <body name="right_side_camera" pos="0.5 -0.55 1.05" euler="1.3 0 0">
      <camera name="right_side" pos="0 0 0" fovy="70"/>
    </body>

    <body name="play_table">
      <geom size="0.2975 0.65 0.005" pos="0.6 0 0.745" type="box" group="2" contype="0" conaffinity="0" rgba="0.92 0.92 0.92 1"/>
    </body>
    <geom name="table_plane" type="plane" size="0.2975 0.65 0.01" pos="0.6 0 0.75" rgba="0 0 0 0" group="3"/>

    <!-- ==================== TASK OBJECTS: Ball Sorting Toy ==================== -->

    <!-- Ball sorting toy (on table, centered) — fixed body, randomized via model.body_pos -->
    <body name="ball-sorting-toy" pos="0.55 0.0 0.81" quat="0.677739 0.682136 -0.201568 -0.186361">
      <geom type="mesh" mesh="ball-sorting-toy-model" quat="1 0 0 0" mass="0.5"
        material="ball-sorting-toy-material" contype="0" conaffinity="0" group="2"/>
      <geom type="mesh" mesh="ball-sorting-toy-collision-0" rgba="0.6587957864419071 0.8772163802960932 0.3861479678943287 1" group="3" contype="1" conaffinity="1" mass="0"/>
      <geom type="mesh" mesh="ball-sorting-toy-collision-1" rgba="0.7588541550623709 0.1893972782798624 0.37943860901026194 1" group="3" contype="1" conaffinity="1" mass="0"/>
      <geom type="mesh" mesh="ball-sorting-toy-collision-2" rgba="0.48933765626564507 0.9695244709947626 0.7338256199344897 1" group="3" contype="1" conaffinity="1" mass="0"/>
      <geom type="mesh" mesh="ball-sorting-toy-collision-3" rgba="0.23897557280588533 0.010786194871451382 0.02649007694402561 1" group="3" contype="1" conaffinity="1" mass="0"/>
      <geom type="mesh" mesh="ball-sorting-toy-collision-4" rgba="0.365777748227627 0.5867165200515327 0.41859934221542294 1" group="3" contype="1" conaffinity="1" mass="0"/>
      <geom type="mesh" mesh="ball-sorting-toy-collision-5" rgba="0.22060896461696222 0.36533829526665573 0.8855212682148677 1" group="3" contype="1" conaffinity="1" mass="0"/>
      <geom type="mesh" mesh="ball-sorting-toy-collision-6" rgba="0.11858030108295536 0.5163241589610037 0.18319386874207833 1" group="3" contype="1" conaffinity="1" mass="0"/>
      <geom type="mesh" mesh="ball-sorting-toy-collision-7" rgba="0.6407027989588587 0.20831995723915475 0.7672722482258051 1" group="3" contype="1" conaffinity="1" mass="0"/>
      <geom type="mesh" mesh="ball-sorting-toy-collision-8" rgba="0.6180980085330194 0.22996009886085444 0.9149751667705702 1" group="3" contype="1" conaffinity="1" mass="0"/>
      <geom type="mesh" mesh="ball-sorting-toy-collision-9" rgba="0.027815516991358535 0.7676452778778768 0.6521782947312494 1" group="3" contype="1" conaffinity="1" mass="0"/>
      <geom type="mesh" mesh="ball-sorting-toy-collision-10" rgba="0.36549753683055586 0.2157999825475222 0.1507458490318847 1" group="3" contype="1" conaffinity="1" mass="0"/>
      <geom type="mesh" mesh="ball-sorting-toy-collision-11" rgba="0.5724580731264256 0.9574179173113297 0.37818080104629515 1" group="3" contype="1" conaffinity="1" mass="0"/>
      <geom type="mesh" mesh="ball-sorting-toy-collision-12" rgba="0.028545911967627013 0.421799339320451 0.26876222033196384 1" group="3" contype="1" conaffinity="1" mass="0"/>
      <geom type="mesh" mesh="ball-sorting-toy-collision-13" rgba="0.39317679740606404 0.7583698173852014 0.2572157684206642 1" group="3" contype="1" conaffinity="1" mass="0"/>
      <geom type="mesh" mesh="ball-sorting-toy-collision-14" rgba="0.76290271086967 0.828190669076819 0.5030786665210893 1" group="3" contype="1" conaffinity="1" mass="0"/>
      <geom type="mesh" mesh="ball-sorting-toy-collision-15" rgba="0.7210697078196127 0.394570153025124 0.5768812352648263 1" group="3" contype="1" conaffinity="1" mass="0"/>
      <geom type="mesh" mesh="ball-sorting-toy-collision-16" rgba="0.3230982282272141 0.6041735403256443 0.7415602637850462 1" group="3" contype="1" conaffinity="1" mass="0"/>
      <geom type="mesh" mesh="ball-sorting-toy-collision-17" rgba="0.020149935784545048 0.7948983570971808 0.7400803946008455 1" group="3" contype="1" conaffinity="1" mass="0"/>
      <geom type="mesh" mesh="ball-sorting-toy-collision-18" rgba="0.4218060819713054 0.3878053171238107 0.7963856716950564 1" group="3" contype="1" conaffinity="1" mass="0"/>
      <geom type="mesh" mesh="ball-sorting-toy-collision-19" rgba="0.3702604055315696 0.21963826810931375 0.9752203407529496 1" group="3" contype="1" conaffinity="1" mass="0"/>
      <geom type="mesh" mesh="ball-sorting-toy-collision-20" rgba="0.2772739121215816 0.7693221903148425 0.3300072096204769 1" group="3" contype="1" conaffinity="1" mass="0"/>
      <geom type="mesh" mesh="ball-sorting-toy-collision-21" rgba="0.19271251059639827 0.13411237008084365 0.7738530955888586 1" group="3" contype="1" conaffinity="1" mass="0"/>
      <geom type="mesh" mesh="ball-sorting-toy-collision-22" rgba="0.36505299041715955 0.14757477754737292 0.8111534966155121 1" group="3" contype="1" conaffinity="1" mass="0"/>
      <geom type="mesh" mesh="ball-sorting-toy-collision-23" rgba="0.6852750202141143 0.37908638044978193 0.12317111468582898 1" group="3" contype="1" conaffinity="1" mass="0"/>
      <geom type="mesh" mesh="ball-sorting-toy-collision-24" rgba="0.6147229546690341 0.716521569573399 0.5258096597230669 1" group="3" contype="1" conaffinity="1" mass="0"/>
      <geom type="mesh" mesh="ball-sorting-toy-collision-25" rgba="0.04357086921121678 0.055910561254217006 0.014238397902254785 1" group="3" contype="1" conaffinity="1" mass="0"/>
      <geom type="mesh" mesh="ball-sorting-toy-collision-26" rgba="0.0466510659879541 0.7259451099496347 0.3523617695330299 1" group="3" contype="1" conaffinity="1" mass="0"/>
      <geom type="mesh" mesh="ball-sorting-toy-collision-27" rgba="0.509139057270697 0.35867890850848927 0.5058152129945177 1" group="3" contype="1" conaffinity="1" mass="0"/>
      <geom type="mesh" mesh="ball-sorting-toy-collision-28" rgba="0.6940930473091614 0.3535238090460737 0.04534065423221534 1" group="3" contype="1" conaffinity="1" mass="0"/>
      <geom type="mesh" mesh="ball-sorting-toy-collision-29" rgba="0.6495502043259175 0.3652080902007333 0.30534441603726126 1" group="3" contype="1" conaffinity="1" mass="0"/>
      <geom type="mesh" mesh="ball-sorting-toy-collision-30" rgba="0.5496254353945454 0.4071851839320664 0.5526002164688095 1" group="3" contype="1" conaffinity="1" mass="0"/>
      <geom type="mesh" mesh="ball-sorting-toy-collision-31" rgba="0.39335742755718217 0.7492551789407093 0.15500381695405785 1" group="3" contype="1" conaffinity="1" mass="0"/>
      <geom type="mesh" mesh="ball-sorting-toy-collision-32" rgba="0.8598782018471182 0.007897311352655478 0.664675978786444 1" group="3" contype="1" conaffinity="1" mass="0"/>
      <geom type="mesh" mesh="ball-sorting-toy-collision-33" rgba="0.4813883111619812 0.7800274877007921 0.15327854350985337 1" group="3" contype="1" conaffinity="1" mass="0"/>
      <geom type="mesh" mesh="ball-sorting-toy-collision-34" rgba="0.7649096138077267 0.07447911460559309 0.6673556309406121 1" group="3" contype="1" conaffinity="1" mass="0"/>
      <geom type="mesh" mesh="ball-sorting-toy-collision-35" rgba="0.5803166895080961 0.1900176528646621 0.9543054953342134 1" group="3" contype="1" conaffinity="1" mass="0"/>
      <geom type="mesh" mesh="ball-sorting-toy-collision-36" rgba="0.738286412576969 0.808620852768266 0.6005410529877504 1" group="3" contype="1" conaffinity="1" mass="0"/>
      <geom type="mesh" mesh="ball-sorting-toy-collision-37" rgba="0.7461875895559988 0.11098023025852433 0.811511908609581 1" group="3" contype="1" conaffinity="1" mass="0"/>
      <geom type="mesh" mesh="ball-sorting-toy-collision-38" rgba="0.48381988437572565 0.599432403536869 0.9906040447406667 1" group="3" contype="1" conaffinity="1" mass="0"/>
      <geom type="mesh" mesh="ball-sorting-toy-collision-39" rgba="0.7343575259014719 0.3200542016196174 0.23810580000614112 1" group="3" contype="1" conaffinity="1" mass="0"/>
      <geom type="mesh" mesh="ball-sorting-toy-collision-40" rgba="0.5127998806173889 0.8193972505037113 0.32767659712797326 1" group="3" contype="1" conaffinity="1" mass="0"/>
      <geom type="mesh" mesh="ball-sorting-toy-collision-41" rgba="0.17086278521609077 0.4147914319456657 0.12506226030019707 1" group="3" contype="1" conaffinity="1" mass="0"/>
      <geom type="mesh" mesh="ball-sorting-toy-collision-42" rgba="0.6263664036675528 0.1770421442332143 0.06785552447074772 1" group="3" contype="1" conaffinity="1" mass="0"/>
      <geom type="mesh" mesh="ball-sorting-toy-collision-43" rgba="0.8023158006623168 0.8984563094730267 0.01806303476682336 1" group="3" contype="1" conaffinity="1" mass="0"/>
      <geom type="mesh" mesh="ball-sorting-toy-collision-44" rgba="0.7757118235226457 0.2453778199102994 0.37548689972690696 1" group="3" contype="1" conaffinity="1" mass="0"/>
      <geom type="mesh" mesh="ball-sorting-toy-collision-45" rgba="0.7565070606386186 0.877167560097369 0.08115953192222825 1" group="3" contype="1" conaffinity="1" mass="0"/>
      <geom type="mesh" mesh="ball-sorting-toy-collision-46" rgba="0.9375474469605997 0.8390079237902862 0.7237902949745956 1" group="3" contype="1" conaffinity="1" mass="0"/>
      <geom type="mesh" mesh="ball-sorting-toy-collision-47" rgba="0.8583350348517212 0.581344263872102 0.3393822938023464 1" group="3" contype="1" conaffinity="1" mass="0"/>
      <geom type="mesh" mesh="ball-sorting-toy-collision-48" rgba="0.162952238651913 0.005498286426415699 0.3509902845554925 1" group="3" contype="1" conaffinity="1" mass="0"/>
      <geom type="mesh" mesh="ball-sorting-toy-collision-49" rgba="0.08046698181661172 0.24289233812824385 0.9992225901381961 1" group="3" contype="1" conaffinity="1" mass="0"/>
      <geom type="mesh" mesh="ball-sorting-toy-collision-50" rgba="0.13649450749649583 0.9863604905002403 0.1964227070645922 1" group="3" contype="1" conaffinity="1" mass="0"/>
      <geom type="mesh" mesh="ball-sorting-toy-collision-51" rgba="0.6387359922228779 0.686000211957101 0.49343657251083284 1" group="3" contype="1" conaffinity="1" mass="0"/>
      <geom type="mesh" mesh="ball-sorting-toy-collision-52" rgba="0.20572789866377705 0.966832219821574 0.9802108719320876 1" group="3" contype="1" conaffinity="1" mass="0"/>
      <geom type="mesh" mesh="ball-sorting-toy-collision-53" rgba="0.8445584797781901 0.5524731646841888 0.087395690068229 1" group="3" contype="1" conaffinity="1" mass="0"/>
      <geom type="mesh" mesh="ball-sorting-toy-collision-54" rgba="0.4037804412543372 0.9253731359008396 0.410192294825659 1" group="3" contype="1" conaffinity="1" mass="0"/>
      <geom type="mesh" mesh="ball-sorting-toy-collision-55" rgba="0.05758577322592762 0.28965827667087574 0.9994678744399148 1" group="3" contype="1" conaffinity="1" mass="0"/>
      <geom type="mesh" mesh="ball-sorting-toy-collision-56" rgba="0.8617570737534774 0.8402420126344347 0.9473632726315314 1" group="3" contype="1" conaffinity="1" mass="0"/>
      <geom type="mesh" mesh="ball-sorting-toy-collision-57" rgba="0.7016968040330613 0.959247109779297 0.558215936458284 1" group="3" contype="1" conaffinity="1" mass="0"/>
      <geom type="mesh" mesh="ball-sorting-toy-collision-58" rgba="0.5697232387308335 0.42565097861177437 0.5539072053715193 1" group="3" contype="1" conaffinity="1" mass="0"/>
      <geom type="mesh" mesh="ball-sorting-toy-collision-59" rgba="0.17612741938746745 0.15026718646803994 0.06047821270838005 1" group="3" contype="1" conaffinity="1" mass="0"/>
      <geom type="mesh" mesh="ball-sorting-toy-collision-60" rgba="0.6361060592715331 0.23756078792610558 0.6885362239224914 1" group="3" contype="1" conaffinity="1" mass="0"/>
      <geom type="mesh" mesh="ball-sorting-toy-collision-61" rgba="0.16616914883589728 0.6071264946100027 0.3983995360332495 1" group="3" contype="1" conaffinity="1" mass="0"/>
      <geom type="mesh" mesh="ball-sorting-toy-collision-62" rgba="0.3262893623283436 0.60635317752026 0.4510637392495642 1" group="3" contype="1" conaffinity="1" mass="0"/>
      <geom type="mesh" mesh="ball-sorting-toy-collision-63" rgba="0.6993717768997557 0.586737093446427 0.6695769991035649 1" group="3" contype="1" conaffinity="1" mass="0"/>
      <geom type="mesh" mesh="ball-sorting-toy-collision-64" rgba="0.6154115338609143 0.367305214914752 0.49733222458267845 1" group="3" contype="1" conaffinity="1" mass="0"/>
      <geom type="mesh" mesh="ball-sorting-toy-collision-65" rgba="0.7977985309827511 0.6422225639650637 0.452949115713265 1" group="3" contype="1" conaffinity="1" mass="0"/>
      <geom type="mesh" mesh="ball-sorting-toy-collision-66" rgba="0.4147818838777746 0.6723855281683668 0.46899414792750305 1" group="3" contype="1" conaffinity="1" mass="0"/>
      <geom type="mesh" mesh="ball-sorting-toy-collision-67" rgba="0.27636073132864836 0.3435653104289066 0.7935162864906408 1" group="3" contype="1" conaffinity="1" mass="0"/>
      <geom type="mesh" mesh="ball-sorting-toy-collision-68" rgba="0.6283920640064804 0.13959279168990713 0.6241386706862471 1" group="3" contype="1" conaffinity="1" mass="0"/>
      <geom type="mesh" mesh="ball-sorting-toy-collision-69" rgba="0.7429645027662702 0.4622940698389594 0.9511844287828987 1" group="3" contype="1" conaffinity="1" mass="0"/>
      <geom type="mesh" mesh="ball-sorting-toy-collision-70" rgba="0.8767211310099742 0.9678995643480487 0.2941317651501566 1" group="3" contype="1" conaffinity="1" mass="0"/>
      <geom type="mesh" mesh="ball-sorting-toy-collision-71" rgba="0.8997771791999758 0.9908207680157058 0.5169738811099865 1" group="3" contype="1" conaffinity="1" mass="0"/>
      <geom type="mesh" mesh="ball-sorting-toy-collision-72" rgba="0.4359482893025449 0.4867960184626341 0.33487693936513974 1" group="3" contype="1" conaffinity="1" mass="0"/>
      <geom type="mesh" mesh="ball-sorting-toy-collision-73" rgba="0.15899114604954212 0.6907849724654126 0.7515939115232729 1" group="3" contype="1" conaffinity="1" mass="0"/>
      <geom type="mesh" mesh="ball-sorting-toy-collision-74" rgba="0.39354482332177165 0.16596741730829878 0.593775747140664 1" group="3" contype="1" conaffinity="1" mass="0"/>
      <geom type="mesh" mesh="ball-sorting-toy-collision-75" rgba="0.9755692297596319 0.8197594007084835 0.15722606024950891 1" group="3" contype="1" conaffinity="1" mass="0"/>
      <geom type="mesh" mesh="ball-sorting-toy-collision-76" rgba="0.31057728146349894 0.8866826503335692 0.6709128060041722 1" group="3" contype="1" conaffinity="1" mass="0"/>
      <geom type="mesh" mesh="ball-sorting-toy-collision-77" rgba="0.4898661577145501 0.7464127370886867 0.20416632749078423 1" group="3" contype="1" conaffinity="1" mass="0"/>
      <geom type="mesh" mesh="ball-sorting-toy-collision-78" rgba="0.7259843532656727 0.2194909446737957 0.9165917873161071 1" group="3" contype="1" conaffinity="1" mass="0"/>
      <geom type="mesh" mesh="ball-sorting-toy-collision-79" rgba="0.5165827173491514 0.68160971229905 0.7504008094063144 1" group="3" contype="1" conaffinity="1" mass="0"/>
      <geom type="mesh" mesh="ball-sorting-toy-collision-80" rgba="0.3111356102970536 0.8338484534914353 0.30716945397611006 1" group="3" contype="1" conaffinity="1" mass="0"/>
      <geom type="mesh" mesh="ball-sorting-toy-collision-81" rgba="0.18356052804848166 0.40350352118085075 0.6755693110584788 1" group="3" contype="1" conaffinity="1" mass="0"/>
      <geom type="mesh" mesh="ball-sorting-toy-collision-82" rgba="0.1878869136609732 0.38157521336735156 0.4501809641194632 1" group="3" contype="1" conaffinity="1" mass="0"/>
      <geom type="mesh" mesh="ball-sorting-toy-collision-83" rgba="0.5007190008362276 0.646023522809987 0.865579056121407 1" group="3" contype="1" conaffinity="1" mass="0"/>
      <geom type="mesh" mesh="ball-sorting-toy-collision-84" rgba="0.3493195744539457 0.6881832441381623 0.4885980937629957 1" group="3" contype="1" conaffinity="1" mass="0"/>
      <geom type="mesh" mesh="ball-sorting-toy-collision-85" rgba="0.22743369415630343 0.9536393484771173 0.7191913936033069 1" group="3" contype="1" conaffinity="1" mass="0"/>
      <geom type="mesh" mesh="ball-sorting-toy-collision-86" rgba="0.3089787231412505 0.6412403658487835 0.8446569470503908 1" group="3" contype="1" conaffinity="1" mass="0"/>
      <geom type="mesh" mesh="ball-sorting-toy-collision-87" rgba="0.5902261438375385 0.2739101266741034 0.889962854399884 1" group="3" contype="1" conaffinity="1" mass="0"/>
      <geom type="mesh" mesh="ball-sorting-toy-collision-88" rgba="0.2270309241754762 0.6893097355531965 0.320366066658222 1" group="3" contype="1" conaffinity="1" mass="0"/>
      <geom type="mesh" mesh="ball-sorting-toy-collision-89" rgba="0.13755394982269942 0.9913959978733066 0.8864611667122987 1" group="3" contype="1" conaffinity="1" mass="0"/>
      <geom type="mesh" mesh="ball-sorting-toy-collision-90" rgba="0.3582228120876366 0.10231751093659303 0.3125398981343058 1" group="3" contype="1" conaffinity="1" mass="0"/>
      <geom type="mesh" mesh="ball-sorting-toy-collision-91" rgba="0.9411649072187863 0.7798046801777262 0.7747252732260657 1" group="3" contype="1" conaffinity="1" mass="0"/>
      <geom type="mesh" mesh="ball-sorting-toy-collision-92" rgba="0.43065065232931865 0.3618550024967928 0.45141413032941224 1" group="3" contype="1" conaffinity="1" mass="0"/>
      <geom type="mesh" mesh="ball-sorting-toy-collision-93" rgba="0.6853064243957842 0.6510498663893606 0.5094573741057977 1" group="3" contype="1" conaffinity="1" mass="0"/>
      <geom type="mesh" mesh="ball-sorting-toy-collision-94" rgba="0.4973096859260494 0.5518060413310177 0.8030758079791199 1" group="3" contype="1" conaffinity="1" mass="0"/>
      <geom type="mesh" mesh="ball-sorting-toy-collision-95" rgba="0.2853607526613826 0.17550400335890592 0.43224777738999076 1" group="3" contype="1" conaffinity="1" mass="0"/>
      <geom type="mesh" mesh="ball-sorting-toy-collision-96" rgba="0.11639220695312791 0.2863612132179796 0.10579103453866234 1" group="3" contype="1" conaffinity="1" mass="0"/>
      <geom type="mesh" mesh="ball-sorting-toy-collision-97" rgba="0.2756315931629314 0.5158852220164983 0.35910247316433375 1" group="3" contype="1" conaffinity="1" mass="0"/>
      <geom type="mesh" mesh="ball-sorting-toy-collision-98" rgba="0.99627688566253 0.8796094874731324 0.9598252134325942 1" group="3" contype="1" conaffinity="1" mass="0"/>
      <geom type="mesh" mesh="ball-sorting-toy-collision-99" rgba="0.8322389486123327 0.9130167248422681 0.38209168054885634 1" group="3" contype="1" conaffinity="1" mass="0"/>
      <geom type="mesh" mesh="ball-sorting-toy-collision-100" rgba="0.6180270820134561 0.04877493546035694 0.2652606258553768 1" group="3" contype="1" conaffinity="1" mass="0"/>
      <geom type="mesh" mesh="ball-sorting-toy-collision-101" rgba="0.6285410891271109 0.6136944633651374 0.6079438008099965 1" group="3" contype="1" conaffinity="1" mass="0"/>
      <geom type="mesh" mesh="ball-sorting-toy-collision-102" rgba="0.3398930435309153 0.6334666693512848 0.515148255162726 1" group="3" contype="1" conaffinity="1" mass="0"/>
      <geom type="mesh" mesh="ball-sorting-toy-collision-103" rgba="0.2226887828381633 0.747664064388591 0.9023633579292868 1" group="3" contype="1" conaffinity="1" mass="0"/>
      <geom type="mesh" mesh="ball-sorting-toy-collision-104" rgba="0.5156400236237639 0.570063468427841 0.03363678594776609 1" group="3" contype="1" conaffinity="1" mass="0"/>
      <geom type="mesh" mesh="ball-sorting-toy-collision-105" rgba="0.5863589967872794 0.09066347894237492 0.749143064757933 1" group="3" contype="1" conaffinity="1" mass="0"/>
      <geom type="mesh" mesh="ball-sorting-toy-collision-106" rgba="0.2689948468186423 0.9970963110978956 0.29321386608190503 1" group="3" contype="1" conaffinity="1" mass="0"/>
      <geom type="mesh" mesh="ball-sorting-toy-collision-107" rgba="0.23036390811322804 0.15506526737258686 0.9092301023438887 1" group="3" contype="1" conaffinity="1" mass="0"/>
      <geom type="mesh" mesh="ball-sorting-toy-collision-108" rgba="0.12597444828984705 0.8024474864461202 0.8570454917818487 1" group="3" contype="1" conaffinity="1" mass="0"/>
      <geom type="mesh" mesh="ball-sorting-toy-collision-109" rgba="0.34990554129924223 0.009368038510135568 0.8804207033640375 1" group="3" contype="1" conaffinity="1" mass="0"/>
      <geom type="mesh" mesh="ball-sorting-toy-collision-110" rgba="0.9537124912196159 0.4614043974814225 0.31231804718073464 1" group="3" contype="1" conaffinity="1" mass="0"/>
      <geom type="mesh" mesh="ball-sorting-toy-collision-111" rgba="0.6634121569674082 0.5764564854900959 0.0281404677471766 1" group="3" contype="1" conaffinity="1" mass="0"/>
      <geom type="mesh" mesh="ball-sorting-toy-collision-112" rgba="0.8615653588435138 0.6653096296311557 0.9937251639444131 1" group="3" contype="1" conaffinity="1" mass="0"/>
      <geom type="mesh" mesh="ball-sorting-toy-collision-113" rgba="0.6976996294367402 0.4681620142568872 0.24591819277904003 1" group="3" contype="1" conaffinity="1" mass="0"/>
      <geom type="mesh" mesh="ball-sorting-toy-collision-114" rgba="0.7635980149499754 0.4055756398093311 0.48634079466485824 1" group="3" contype="1" conaffinity="1" mass="0"/>
      <geom type="mesh" mesh="ball-sorting-toy-collision-115" rgba="0.027536178673396083 0.7897753188695865 0.8238954033077885 1" group="3" contype="1" conaffinity="1" mass="0"/>
      <geom type="mesh" mesh="ball-sorting-toy-collision-116" rgba="0.39096099569906806 0.553953817006457 0.9501032221784337 1" group="3" contype="1" conaffinity="1" mass="0"/>
      <geom type="mesh" mesh="ball-sorting-toy-collision-117" rgba="0.45766577742821146 0.3634320494524056 0.013536606746700541 1" group="3" contype="1" conaffinity="1" mass="0"/>
      <geom type="mesh" mesh="ball-sorting-toy-collision-118" rgba="0.1715836075044359 0.7987880880074106 0.968451773839224 1" group="3" contype="1" conaffinity="1" mass="0"/>
      <geom type="mesh" mesh="ball-sorting-toy-collision-119" rgba="0.8210016296662934 0.18080096464993245 0.9069207546528973 1" group="3" contype="1" conaffinity="1" mass="0"/>
      <geom type="mesh" mesh="ball-sorting-toy-collision-120" rgba="0.4261377617922213 0.2807778386061299 0.284646327997813 1" group="3" contype="1" conaffinity="1" mass="0"/>
      <geom type="mesh" mesh="ball-sorting-toy-collision-121" rgba="0.8041579467227927 0.1497632021311196 0.72806886914239 1" group="3" contype="1" conaffinity="1" mass="0"/>
      <geom type="mesh" mesh="ball-sorting-toy-collision-122" rgba="0.9407886971036069 0.7302764470633821 0.5792194012850742 1" group="3" contype="1" conaffinity="1" mass="0"/>
      <geom type="mesh" mesh="ball-sorting-toy-collision-123" rgba="0.6370440456901889 0.5852230268579706 0.17568488863923082 1" group="3" contype="1" conaffinity="1" mass="0"/>
      <geom type="mesh" mesh="ball-sorting-toy-collision-124" rgba="0.7887863686311127 0.4338685733409102 0.2578818611887481 1" group="3" contype="1" conaffinity="1" mass="0"/>
      <geom type="mesh" mesh="ball-sorting-toy-collision-125" rgba="0.8811036599244534 0.6738727510906517 0.4112032256830177 1" group="3" contype="1" conaffinity="1" mass="0"/>
      <geom type="mesh" mesh="ball-sorting-toy-collision-126" rgba="0.7442633340086957 0.47629786449447187 0.2682157400468591 1" group="3" contype="1" conaffinity="1" mass="0"/>
      <geom type="mesh" mesh="ball-sorting-toy-collision-127" rgba="0.34871183029437947 0.9439586798911686 0.560145135915227 1" group="3" contype="1" conaffinity="1" mass="0"/>
      <geom type="mesh" mesh="ball-sorting-toy-collision-128" rgba="0.9352645919591019 0.6815081867892423 0.4605963214338342 1" group="3" contype="1" conaffinity="1" mass="0"/>
      <geom type="mesh" mesh="ball-sorting-toy-collision-129" rgba="0.23666144442844117 0.0694698078091136 0.023680782459893246 1" group="3" contype="1" conaffinity="1" mass="0"/>
      <geom type="mesh" mesh="ball-sorting-toy-collision-130" rgba="0.7945665935067266 0.8035791598176097 0.44198130622441656 1" group="3" contype="1" conaffinity="1" mass="0"/>
      <geom type="mesh" mesh="ball-sorting-toy-collision-131" rgba="0.4795214929705188 0.3226896341463943 0.8536006101469725 1" group="3" contype="1" conaffinity="1" mass="0"/>
      <geom type="mesh" mesh="ball-sorting-toy-collision-132" rgba="0.12963808067796379 0.11875244752531111 0.12346802534542722 1" group="3" contype="1" conaffinity="1" mass="0"/>
      <geom type="mesh" mesh="ball-sorting-toy-collision-133" rgba="0.30721236914101024 0.6528443202204929 0.8007081594233417 1" group="3" contype="1" conaffinity="1" mass="0"/>
      <geom type="mesh" mesh="ball-sorting-toy-collision-134" rgba="0.034668343670551494 0.5856354534618479 0.45430050781248954 1" group="3" contype="1" conaffinity="1" mass="0"/>
      <geom type="mesh" mesh="ball-sorting-toy-collision-135" rgba="0.5598721799797514 0.6145467909587502 0.6591967058264049 1" group="3" contype="1" conaffinity="1" mass="0"/>
      <geom type="mesh" mesh="ball-sorting-toy-collision-136" rgba="0.16915245033578752 0.2765444254864703 0.20206910979661763 1" group="3" contype="1" conaffinity="1" mass="0"/>
      <geom type="mesh" mesh="ball-sorting-toy-collision-137" rgba="0.8768789073322318 0.003250582258093382 0.6223060993249647 1" group="3" contype="1" conaffinity="1" mass="0"/>
      <geom type="mesh" mesh="ball-sorting-toy-collision-138" rgba="0.728367473125102 0.8203477544805629 0.29958945154880257 1" group="3" contype="1" conaffinity="1" mass="0"/>
      <geom type="mesh" mesh="ball-sorting-toy-collision-139" rgba="0.49409374990453414 0.9935179009264095 0.8908573290000604 1" group="3" contype="1" conaffinity="1" mass="0"/>
      <geom type="mesh" mesh="ball-sorting-toy-collision-140" rgba="0.4595836888857463 0.032263606249968935 0.7457834114392533 1" group="3" contype="1" conaffinity="1" mass="0"/>
      <geom type="mesh" mesh="ball-sorting-toy-collision-141" rgba="0.4301950436425337 0.42930202317944777 0.18420116873617298 1" group="3" contype="1" conaffinity="1" mass="0"/>
      <geom type="mesh" mesh="ball-sorting-toy-collision-142" rgba="0.7533986676920007 0.6691886007342951 0.9320029168310556 1" group="3" contype="1" conaffinity="1" mass="0"/>
      <geom type="mesh" mesh="ball-sorting-toy-collision-143" rgba="0.1925565463932415 0.5849063480369628 0.9627990844353949 1" group="3" contype="1" conaffinity="1" mass="0"/>
      <geom type="mesh" mesh="ball-sorting-toy-collision-144" rgba="0.21301713903998076 0.9195081986880536 0.3105705975182754 1" group="3" contype="1" conaffinity="1" mass="0"/>
      <geom type="mesh" mesh="ball-sorting-toy-collision-145" rgba="0.11812954584867652 0.19831236891884074 0.36143968726981635 1" group="3" contype="1" conaffinity="1" mass="0"/>
      <geom type="mesh" mesh="ball-sorting-toy-collision-146" rgba="0.9695908975746719 0.9914799143900769 0.4601501962561363 1" group="3" contype="1" conaffinity="1" mass="0"/>
      <geom type="mesh" mesh="ball-sorting-toy-collision-147" rgba="0.3501809236596827 0.6510573680521523 0.42810094127190157 1" group="3" contype="1" conaffinity="1" mass="0"/>
      <geom type="mesh" mesh="ball-sorting-toy-collision-148" rgba="0.15252970605620464 0.2662666981232221 0.31306257943181437 1" group="3" contype="1" conaffinity="1" mass="0"/>
      <geom type="mesh" mesh="ball-sorting-toy-collision-149" rgba="0.6397336172807453 0.5982954821087022 0.797260690990469 1" group="3" contype="1" conaffinity="1" mass="0"/>
      <geom type="mesh" mesh="ball-sorting-toy-collision-150" rgba="0.8821579235901624 0.7236772374845957 0.4605643122202575 1" group="3" contype="1" conaffinity="1" mass="0"/>
      <geom type="mesh" mesh="ball-sorting-toy-collision-151" rgba="0.8901548595830971 0.4533193323312855 0.4909252427622003 1" group="3" contype="1" conaffinity="1" mass="0"/>
      <geom type="mesh" mesh="ball-sorting-toy-collision-152" rgba="0.33212299969460235 0.2389442964733236 0.44415655392801945 1" group="3" contype="1" conaffinity="1" mass="0"/>
      <geom type="mesh" mesh="ball-sorting-toy-collision-153" rgba="0.7928041483253974 0.34483711166074904 0.685669887022433 1" group="3" contype="1" conaffinity="1" mass="0"/>
      <geom type="mesh" mesh="ball-sorting-toy-collision-154" rgba="0.3265649471216937 0.7739027125868905 0.06896749655415724 1" group="3" contype="1" conaffinity="1" mass="0"/>
      <geom type="mesh" mesh="ball-sorting-toy-collision-155" rgba="0.1642951796091935 0.5631332766350593 0.6723635905588335 1" group="3" contype="1" conaffinity="1" mass="0"/>
      <geom type="mesh" mesh="ball-sorting-toy-collision-156" rgba="0.533546620570745 0.9594871534941899 0.07377074223362146 1" group="3" contype="1" conaffinity="1" mass="0"/>
      <geom type="mesh" mesh="ball-sorting-toy-collision-157" rgba="0.17099183207604562 0.79554619673814 0.01484458751638884 1" group="3" contype="1" conaffinity="1" mass="0"/>
      <geom type="mesh" mesh="ball-sorting-toy-collision-158" rgba="0.912607993957504 0.26374503372604685 0.9799851085325577 1" group="3" contype="1" conaffinity="1" mass="0"/>
      <geom type="mesh" mesh="ball-sorting-toy-collision-159" rgba="0.19385761040734095 0.901511530418162 0.032629779521926805 1" group="3" contype="1" conaffinity="1" mass="0"/>
      <geom type="mesh" mesh="ball-sorting-toy-collision-160" rgba="0.9298040425538141 0.7116529394091505 0.9207360085947013 1" group="3" contype="1" conaffinity="1" mass="0"/>
      <geom type="mesh" mesh="ball-sorting-toy-collision-161" rgba="0.7288590336071902 0.96606369788425 0.46211361176891896 1" group="3" contype="1" conaffinity="1" mass="0"/>
      <geom type="mesh" mesh="ball-sorting-toy-collision-162" rgba="0.8821651822940881 0.2708735576227015 0.8979748631199235 1" group="3" contype="1" conaffinity="1" mass="0"/>
      <geom type="mesh" mesh="ball-sorting-toy-collision-163" rgba="0.003091796460144458 0.5551436899236261 0.05038663994628445 1" group="3" contype="1" conaffinity="1" mass="0"/>
      <geom type="mesh" mesh="ball-sorting-toy-collision-164" rgba="0.803393615898417 0.30754116904515605 0.16180552967883577 1" group="3" contype="1" conaffinity="1" mass="0"/>
      <geom type="mesh" mesh="ball-sorting-toy-collision-165" rgba="0.2528253549549152 0.2878723415193968 0.692899412974731 1" group="3" contype="1" conaffinity="1" mass="0"/>
      <geom type="mesh" mesh="ball-sorting-toy-collision-166" rgba="0.3155639215315602 0.954497112710486 0.16204535666878683 1" group="3" contype="1" conaffinity="1" mass="0"/>
      <geom type="mesh" mesh="ball-sorting-toy-collision-167" rgba="0.08486531417367849 0.9168513078963118 0.317728989818891 1" group="3" contype="1" conaffinity="1" mass="0"/>
      <geom type="mesh" mesh="ball-sorting-toy-collision-168" rgba="0.5389418769504015 0.5224313276765525 0.6278189886784412 1" group="3" contype="1" conaffinity="1" mass="0"/>
      <geom type="mesh" mesh="ball-sorting-toy-collision-169" rgba="0.44202095007960385 0.9887475731702369 0.41670783165398595 1" group="3" contype="1" conaffinity="1" mass="0"/>
      <geom type="mesh" mesh="ball-sorting-toy-collision-170" rgba="0.3341431944272587 0.49087197231750246 0.5965485641303947 1" group="3" contype="1" conaffinity="1" mass="0"/>
      <geom type="mesh" mesh="ball-sorting-toy-collision-171" rgba="0.5816352615752506 0.1656087685840767 0.9721495268973428 1" group="3" contype="1" conaffinity="1" mass="0"/>
      <geom type="mesh" mesh="ball-sorting-toy-collision-172" rgba="0.26657457276596974 0.5433720931449719 0.8007261664024162 1" group="3" contype="1" conaffinity="1" mass="0"/>
      <geom type="mesh" mesh="ball-sorting-toy-collision-173" rgba="0.28947414976955854 0.1354310698771528 0.13821073200796963 1" group="3" contype="1" conaffinity="1" mass="0"/>
      <geom type="mesh" mesh="ball-sorting-toy-collision-174" rgba="0.12600782177035041 0.4618727820326436 0.10940562238311669 1" group="3" contype="1" conaffinity="1" mass="0"/>
      <geom type="mesh" mesh="ball-sorting-toy-collision-175" rgba="0.43366335537932676 0.45342953847092404 0.47621137603507424 1" group="3" contype="1" conaffinity="1" mass="0"/>
      <geom type="mesh" mesh="ball-sorting-toy-collision-176" rgba="0.5299476570153465 0.2769856640523558 0.48560476285526133 1" group="3" contype="1" conaffinity="1" mass="0"/>
      <geom type="mesh" mesh="ball-sorting-toy-collision-177" rgba="0.04764610141472869 0.4416913452142375 0.9049844731578607 1" group="3" contype="1" conaffinity="1" mass="0"/>
      <geom type="mesh" mesh="ball-sorting-toy-collision-178" rgba="0.4096410858302917 0.7467962879736909 0.8475110847345253 1" group="3" contype="1" conaffinity="1" mass="0"/>
      <geom type="mesh" mesh="ball-sorting-toy-collision-179" rgba="0.3104542747912029 0.5610989878098631 0.39886311441282163 1" group="3" contype="1" conaffinity="1" mass="0"/>
      <geom type="mesh" mesh="ball-sorting-toy-collision-180" rgba="0.08261128751418045 0.7625194805122313 0.2036366773338496 1" group="3" contype="1" conaffinity="1" mass="0"/>
      <geom type="mesh" mesh="ball-sorting-toy-collision-181" rgba="0.5006438580120329 0.6196839213422728 0.09011017575386404 1" group="3" contype="1" conaffinity="1" mass="0"/>
      <geom type="mesh" mesh="ball-sorting-toy-collision-182" rgba="0.3620045674531791 0.4430652335671126 0.3894862856750234 1" group="3" contype="1" conaffinity="1" mass="0"/>
      <geom type="mesh" mesh="ball-sorting-toy-collision-183" rgba="0.030846776286953093 0.9557863647519989 0.4480757150138869 1" group="3" contype="1" conaffinity="1" mass="0"/>
      <geom type="mesh" mesh="ball-sorting-toy-collision-184" rgba="0.6591507854130946 0.49313187117578794 0.6722780341922522 1" group="3" contype="1" conaffinity="1" mass="0"/>
      <geom type="mesh" mesh="ball-sorting-toy-collision-185" rgba="0.03242558199420664 0.2796434402116028 0.5229217929470555 1" group="3" contype="1" conaffinity="1" mass="0"/>
      <geom type="mesh" mesh="ball-sorting-toy-collision-186" rgba="0.5160653900132746 0.4027934175704875 0.7031809871078911 1" group="3" contype="1" conaffinity="1" mass="0"/>
      <geom type="mesh" mesh="ball-sorting-toy-collision-187" rgba="0.38742549221156863 0.4056533509681721 0.196899567427416 1" group="3" contype="1" conaffinity="1" mass="0"/>
      <geom type="mesh" mesh="ball-sorting-toy-collision-188" rgba="0.034195101778128234 0.2776563451375218 0.31948585678256836 1" group="3" contype="1" conaffinity="1" mass="0"/>
      <geom type="mesh" mesh="ball-sorting-toy-collision-189" rgba="0.015492012713996917 0.9973027194893761 0.12711583729433396 1" group="3" contype="1" conaffinity="1" mass="0"/>
      <geom type="mesh" mesh="ball-sorting-toy-collision-190" rgba="0.9896757309748133 0.24593088815135233 0.24228120601442593 1" group="3" contype="1" conaffinity="1" mass="0"/>
      <geom type="mesh" mesh="ball-sorting-toy-collision-191" rgba="0.7798478584021789 0.41593440236443824 0.801355976972516 1" group="3" contype="1" conaffinity="1" mass="0"/>
      <geom type="mesh" mesh="ball-sorting-toy-collision-192" rgba="0.9593449126874725 0.4387182110150192 0.6269450309655741 1" group="3" contype="1" conaffinity="1" mass="0"/>
      <geom type="mesh" mesh="ball-sorting-toy-collision-193" rgba="0.5074893892707263 0.7121925212822527 0.4881100211467767 1" group="3" contype="1" conaffinity="1" mass="0"/>
      <geom type="mesh" mesh="ball-sorting-toy-collision-194" rgba="0.635084558895939 0.8223759687776471 0.5871095163027151 1" group="3" contype="1" conaffinity="1" mass="0"/>
      <geom type="mesh" mesh="ball-sorting-toy-collision-195" rgba="0.019743230248726706 0.2133159633321946 0.34203141329930165 1" group="3" contype="1" conaffinity="1" mass="0"/>
      <geom type="mesh" mesh="ball-sorting-toy-collision-196" rgba="0.27290339412403364 0.7572637222744689 0.938350798963988 1" group="3" contype="1" conaffinity="1" mass="0"/>
      <geom type="mesh" mesh="ball-sorting-toy-collision-197" rgba="0.062129480805148685 0.9500944100937561 0.6999286502371064 1" group="3" contype="1" conaffinity="1" mass="0"/>
      <geom type="mesh" mesh="ball-sorting-toy-collision-198" rgba="0.7770033137427718 0.26461140057372723 0.44169843430882294 1" group="3" contype="1" conaffinity="1" mass="0"/>
      <geom type="mesh" mesh="ball-sorting-toy-collision-199" rgba="0.972146381999291 0.2229834185647518 0.8017184095398816 1" group="3" contype="1" conaffinity="1" mass="0"/>
      <geom type="mesh" mesh="ball-sorting-toy-collision-200" rgba="0.8752616968769065 0.2858554397488098 0.4941172216911397 1" group="3" contype="1" conaffinity="1" mass="0"/>
      <geom type="mesh" mesh="ball-sorting-toy-collision-201" rgba="0.21964969565708348 0.10857450673363978 0.36227463058405074 1" group="3" contype="1" conaffinity="1" mass="0"/>
      <geom type="mesh" mesh="ball-sorting-toy-collision-202" rgba="0.45172548143431 0.6176830405480779 0.4224286665895176 1" group="3" contype="1" conaffinity="1" mass="0"/>
      <geom type="mesh" mesh="ball-sorting-toy-collision-203" rgba="0.9060293008014337 0.38345398095663463 0.6653769269634822 1" group="3" contype="1" conaffinity="1" mass="0"/>
      <geom type="mesh" mesh="ball-sorting-toy-collision-204" rgba="0.9673069450726236 0.775143847831622 0.9099875049041587 1" group="3" contype="1" conaffinity="1" mass="0"/>
      <geom type="mesh" mesh="ball-sorting-toy-collision-205" rgba="0.01256511793531867 0.4641311910427792 0.3435351789757508 1" group="3" contype="1" conaffinity="1" mass="0"/>
      <geom type="mesh" mesh="ball-sorting-toy-collision-206" rgba="0.18347427818581075 0.48776789568128753 0.33270785150181437 1" group="3" contype="1" conaffinity="1" mass="0"/>
      <geom type="mesh" mesh="ball-sorting-toy-collision-207" rgba="0.3582409551535298 0.30580725791495744 0.4767420525865297 1" group="3" contype="1" conaffinity="1" mass="0"/>
      <geom type="mesh" mesh="ball-sorting-toy-collision-208" rgba="0.8830511451337476 0.8669291880463773 0.5038645106562717 1" group="3" contype="1" conaffinity="1" mass="0"/>
      <geom type="mesh" mesh="ball-sorting-toy-collision-209" rgba="0.434298005297564 0.36692361870223655 0.3380638931850891 1" group="3" contype="1" conaffinity="1" mass="0"/>
      <geom type="mesh" mesh="ball-sorting-toy-collision-210" rgba="0.5764635980370053 0.7934663777728371 0.3260127956747415 1" group="3" contype="1" conaffinity="1" mass="0"/>
      <geom type="mesh" mesh="ball-sorting-toy-collision-211" rgba="0.7619564491841 0.5407524395604706 0.7132774688378791 1" group="3" contype="1" conaffinity="1" mass="0"/>
      <geom type="mesh" mesh="ball-sorting-toy-collision-212" rgba="0.27300396405740424 0.6136654060120414 0.688690203909338 1" group="3" contype="1" conaffinity="1" mass="0"/>
      <geom type="mesh" mesh="ball-sorting-toy-collision-213" rgba="0.7876829847524872 0.6948561110406785 0.7677051823123647 1" group="3" contype="1" conaffinity="1" mass="0"/>
      <geom type="mesh" mesh="ball-sorting-toy-collision-214" rgba="0.7967064429658394 0.7189048779432271 0.838230650568043 1" group="3" contype="1" conaffinity="1" mass="0"/>
      <geom type="mesh" mesh="ball-sorting-toy-collision-215" rgba="0.12415092230308622 0.7375620379745833 0.22781957814488552 1" group="3" contype="1" conaffinity="1" mass="0"/>
      <geom type="mesh" mesh="ball-sorting-toy-collision-216" rgba="0.14321610141829288 0.2502284186036806 0.6996819859520816 1" group="3" contype="1" conaffinity="1" mass="0"/>
      <geom type="mesh" mesh="ball-sorting-toy-collision-217" rgba="0.6952493237403725 0.48133976322814165 0.12180026710387581 1" group="3" contype="1" conaffinity="1" mass="0"/>
      <geom type="mesh" mesh="ball-sorting-toy-collision-218" rgba="0.2658650543108928 0.5668326890562015 0.4148300529626837 1" group="3" contype="1" conaffinity="1" mass="0"/>
      <geom type="mesh" mesh="ball-sorting-toy-collision-219" rgba="0.17028207109926885 0.8843014036749928 0.37616938224376495 1" group="3" contype="1" conaffinity="1" mass="0"/>
      <geom type="mesh" mesh="ball-sorting-toy-collision-220" rgba="0.4400343390178645 0.26854519031014623 0.3900058129485804 1" group="3" contype="1" conaffinity="1" mass="0"/>
      <geom type="mesh" mesh="ball-sorting-toy-collision-221" rgba="0.7474950297682333 0.4342459076820393 0.983156486933339 1" group="3" contype="1" conaffinity="1" mass="0"/>
      <geom type="mesh" mesh="ball-sorting-toy-collision-222" rgba="0.8705350212774249 0.4464083107298169 0.00149455107055807 1" group="3" contype="1" conaffinity="1" mass="0"/>
      <geom type="mesh" mesh="ball-sorting-toy-collision-223" rgba="0.19758893706098601 0.8738586674711831 0.43581875710677576 1" group="3" contype="1" conaffinity="1" mass="0"/>
      <geom type="mesh" mesh="ball-sorting-toy-collision-224" rgba="0.7633814820807572 0.21180555880553398 0.1190071148734867 1" group="3" contype="1" conaffinity="1" mass="0"/>
      <geom type="mesh" mesh="ball-sorting-toy-collision-225" rgba="0.1366016921690859 0.8691924103299858 0.557897041007612 1" group="3" contype="1" conaffinity="1" mass="0"/>
      <geom type="mesh" mesh="ball-sorting-toy-collision-226" rgba="0.4054681060873352 0.25748359627461037 0.7634264595830841 1" group="3" contype="1" conaffinity="1" mass="0"/>
      <geom type="mesh" mesh="ball-sorting-toy-collision-227" rgba="0.7900663440425141 0.8002272758458885 0.903853626732806 1" group="3" contype="1" conaffinity="1" mass="0"/>
      <geom type="mesh" mesh="ball-sorting-toy-collision-228" rgba="0.06484488462374116 0.39091326666665105 0.4524604289245895 1" group="3" contype="1" conaffinity="1" mass="0"/>
      <geom type="mesh" mesh="ball-sorting-toy-collision-229" rgba="0.44602556268776894 0.6764731318106136 0.9107166267454143 1" group="3" contype="1" conaffinity="1" mass="0"/>
      <geom type="mesh" mesh="ball-sorting-toy-collision-230" rgba="0.3947505607950781 0.31151500985353653 0.2707121573804351 1" group="3" contype="1" conaffinity="1" mass="0"/>
      <geom type="mesh" mesh="ball-sorting-toy-collision-231" rgba="0.11526617195025635 0.4741467176178409 0.7996272579375182 1" group="3" contype="1" conaffinity="1" mass="0"/>
      <geom type="mesh" mesh="ball-sorting-toy-collision-232" rgba="0.678795827662293 0.5950445451297853 0.47470609162573163 1" group="3" contype="1" conaffinity="1" mass="0"/>
      <geom type="mesh" mesh="ball-sorting-toy-collision-233" rgba="0.8860694023955864 0.961966380119461 0.3235016239622188 1" group="3" contype="1" conaffinity="1" mass="0"/>
      <geom type="mesh" mesh="ball-sorting-toy-collision-234" rgba="0.3569434709135735 0.48013930626435053 0.7720511751215383 1" group="3" contype="1" conaffinity="1" mass="0"/>
      <geom type="mesh" mesh="ball-sorting-toy-collision-235" rgba="0.022951007531917256 0.2839659881372971 0.23873916062650336 1" group="3" contype="1" conaffinity="1" mass="0"/>
      <geom type="mesh" mesh="ball-sorting-toy-collision-236" rgba="0.13675207827488178 0.18199088825827803 0.5873737893974168 1" group="3" contype="1" conaffinity="1" mass="0"/>
      <geom type="mesh" mesh="ball-sorting-toy-collision-237" rgba="0.9381129278577192 0.42511040774104947 0.2112414670331073 1" group="3" contype="1" conaffinity="1" mass="0"/>
      <geom type="mesh" mesh="ball-sorting-toy-collision-238" rgba="0.10490681948460645 0.8036304882009352 0.44756091028834755 1" group="3" contype="1" conaffinity="1" mass="0"/>
      <geom type="mesh" mesh="ball-sorting-toy-collision-239" rgba="0.7586016800714489 0.7425055361860678 0.25239469261023395 1" group="3" contype="1" conaffinity="1" mass="0"/>
      <geom type="mesh" mesh="ball-sorting-toy-collision-240" rgba="0.8969804893533186 0.5844942693989138 0.30208203493029406 1" group="3" contype="1" conaffinity="1" mass="0"/>
      <geom type="mesh" mesh="ball-sorting-toy-collision-241" rgba="0.5137677489249481 0.8386465058345428 0.432533850877853 1" group="3" contype="1" conaffinity="1" mass="0"/>
      <geom type="mesh" mesh="ball-sorting-toy-collision-242" rgba="0.37533573209831894 0.7655184293760744 0.8783897903450767 1" group="3" contype="1" conaffinity="1" mass="0"/>
      <geom type="mesh" mesh="ball-sorting-toy-collision-243" rgba="0.5882262244519524 0.5063477137912592 0.3527672181666295 1" group="3" contype="1" conaffinity="1" mass="0"/>
      <geom type="mesh" mesh="ball-sorting-toy-collision-244" rgba="0.6592095877763127 0.09484112840499581 0.613298821657525 1" group="3" contype="1" conaffinity="1" mass="0"/>
      <geom type="mesh" mesh="ball-sorting-toy-collision-245" rgba="0.33991551163234845 0.1293235171363709 0.5174278622075512 1" group="3" contype="1" conaffinity="1" mass="0"/>
      <geom type="mesh" mesh="ball-sorting-toy-collision-246" rgba="0.01023158360415688 0.019367953921100134 0.9147321836055161 1" group="3" contype="1" conaffinity="1" mass="0"/>
      <geom type="mesh" mesh="ball-sorting-toy-collision-247" rgba="0.515411304883411 0.8043058979633186 0.5559041315370338 1" group="3" contype="1" conaffinity="1" mass="0"/>
      <geom type="mesh" mesh="ball-sorting-toy-collision-248" rgba="0.6838675787484212 0.5388309827905636 0.8391673850688646 1" group="3" contype="1" conaffinity="1" mass="0"/>
      <geom type="mesh" mesh="ball-sorting-toy-collision-249" rgba="0.16423631284329876 0.6153051471909763 0.4510566949349476 1" group="3" contype="1" conaffinity="1" mass="0"/>
      <geom type="mesh" mesh="ball-sorting-toy-collision-250" rgba="0.7977333165389966 0.7050262593025814 0.3929159944974454 1" group="3" contype="1" conaffinity="1" mass="0"/>
      <geom type="mesh" mesh="ball-sorting-toy-collision-251" rgba="0.1571789872957341 0.7291791616651534 0.04521354725726934 1" group="3" contype="1" conaffinity="1" mass="0"/>
      <geom type="mesh" mesh="ball-sorting-toy-collision-252" rgba="0.46977754855228915 0.3783893752845261 0.842344285320089 1" group="3" contype="1" conaffinity="1" mass="0"/>
      <geom type="mesh" mesh="ball-sorting-toy-collision-253" rgba="0.3533577396033526 0.910441640929587 0.790123986083868 1" group="3" contype="1" conaffinity="1" mass="0"/>
      <geom type="mesh" mesh="ball-sorting-toy-collision-254" rgba="0.1458760333994369 0.9952957543422503 0.4247481452595694 1" group="3" contype="1" conaffinity="1" mass="0"/>
      <geom type="mesh" mesh="ball-sorting-toy-collision-255" rgba="0.9340948082497335 0.4893280939307436 0.7442652328399458 1" group="3" contype="1" conaffinity="1" mass="0"/>
      <geom type="mesh" mesh="ball-sorting-toy-collision-256" rgba="0.031830921603289375 0.5060332706252147 0.7294330692344825 1" group="3" contype="1" conaffinity="1" mass="0"/>
      <geom type="mesh" mesh="ball-sorting-toy-collision-257" rgba="0.46953863297370324 0.48658202041477494 0.8718947543481174 1" group="3" contype="1" conaffinity="1" mass="0"/>
      <geom type="mesh" mesh="ball-sorting-toy-collision-258" rgba="0.7719084780171471 0.8966599133864608 0.2892702427303788 1" group="3" contype="1" conaffinity="1" mass="0"/>
      <geom type="mesh" mesh="ball-sorting-toy-collision-259" rgba="0.6525891163024246 0.28639963384764255 0.3943151165240224 1" group="3" contype="1" conaffinity="1" mass="0"/>
      <geom type="mesh" mesh="ball-sorting-toy-collision-260" rgba="0.5257891112482109 0.7461012717442456 0.4632941927677825 1" group="3" contype="1" conaffinity="1" mass="0"/>
      <geom type="mesh" mesh="ball-sorting-toy-collision-261" rgba="0.4346368128572744 0.1506805098335352 0.9455116731862615 1" group="3" contype="1" conaffinity="1" mass="0"/>
      <geom type="mesh" mesh="ball-sorting-toy-collision-262" rgba="0.3670756429549016 0.13326068782080236 0.9114737629528621 1" group="3" contype="1" conaffinity="1" mass="0"/>
      <geom type="mesh" mesh="ball-sorting-toy-collision-263" rgba="0.3270207694429098 0.5439745196791045 0.544599771879932 1" group="3" contype="1" conaffinity="1" mass="0"/>
      <geom type="mesh" mesh="ball-sorting-toy-collision-264" rgba="0.08238034399198779 0.2059650340420739 0.6215284663078317 1" group="3" contype="1" conaffinity="1" mass="0"/>
      <geom type="mesh" mesh="ball-sorting-toy-collision-265" rgba="0.6549626077074238 0.1770778595174105 0.6214515997621686 1" group="3" contype="1" conaffinity="1" mass="0"/>
      <geom type="mesh" mesh="ball-sorting-toy-collision-266" rgba="0.9181020623954539 0.09209089545334659 0.9282444840080715 1" group="3" contype="1" conaffinity="1" mass="0"/>
      <geom type="mesh" mesh="ball-sorting-toy-collision-267" rgba="0.41613024653981734 0.2011434127758197 0.44581453636324153 1" group="3" contype="1" conaffinity="1" mass="0"/>
      <geom type="mesh" mesh="ball-sorting-toy-collision-268" rgba="0.6967049281063871 0.6557735486045777 0.6855621969273271 1" group="3" contype="1" conaffinity="1" mass="0"/>
      <geom type="mesh" mesh="ball-sorting-toy-collision-269" rgba="0.7573166199565254 0.8073243671067323 0.3317933006357031 1" group="3" contype="1" conaffinity="1" mass="0"/>
      <geom type="mesh" mesh="ball-sorting-toy-collision-270" rgba="0.41827362412235847 0.8938669684053047 0.5859190654473881 1" group="3" contype="1" conaffinity="1" mass="0"/>
      <geom type="mesh" mesh="ball-sorting-toy-collision-271" rgba="0.22920772044346427 0.7688204596330557 0.1772554350267881 1" group="3" contype="1" conaffinity="1" mass="0"/>
      <geom type="mesh" mesh="ball-sorting-toy-collision-272" rgba="0.17748391268566155 0.5979317392621388 0.018445357513430127 1" group="3" contype="1" conaffinity="1" mass="0"/>
      <geom type="mesh" mesh="ball-sorting-toy-collision-273" rgba="0.6067637141022347 0.5761147803702663 0.8826745332450494 1" group="3" contype="1" conaffinity="1" mass="0"/>
      <geom type="mesh" mesh="ball-sorting-toy-collision-274" rgba="0.8394612002733832 0.6610726363590648 0.08305516690193104 1" group="3" contype="1" conaffinity="1" mass="0"/>
      <geom type="mesh" mesh="ball-sorting-toy-collision-275" rgba="0.6693789537337523 0.8849424751604571 0.8989586610934883 1" group="3" contype="1" conaffinity="1" mass="0"/>
      <geom type="mesh" mesh="ball-sorting-toy-collision-276" rgba="0.35339122523846156 0.9906065988117593 0.35406932536555047 1" group="3" contype="1" conaffinity="1" mass="0"/>
      <geom type="mesh" mesh="ball-sorting-toy-collision-277" rgba="0.5840926147798214 0.6415078593409638 0.6582040668095742 1" group="3" contype="1" conaffinity="1" mass="0"/>
    </body>

    <!-- Cylinder 1: Red -->
    <body name="cylinder-1" pos="0.45 0.12 0.78" quat="0 0 1 0">
      <freejoint name="cylinder-1"/>
      <geom name="cylinder-1-geom" type="cylinder" size="0.0175 0.0175"
        rgba="0.7421875 0.25 0.2656 1" mass="0.05" condim="6"
        solimp="0.998 0.998 0.001" solref="0.004 1" friction="3.0 0.1 0.01" density="0" priority="1"/>
    </body>

    <!-- Cylinder 2: Blue -->
    <body name="cylinder-2" pos="0.50 -0.15 0.78" quat="0 0 1 0">
      <freejoint name="cylinder-2"/>
      <geom name="cylinder-2-geom" type="cylinder" size="0.0175 0.0175"
        rgba="0.1953125 0.3203125 0.54296875 1" mass="0.05" condim="6"
        solimp="0.998 0.998 0.001" solref="0.004 1" friction="3.0 0.1 0.01" density="0" priority="1"/>
    </body>

    <!-- Cylinder 3: Green -->
    <body name="cylinder-3" pos="0.60 -0.08 0.78" quat="0 0 1 0">
      <freejoint name="cylinder-3"/>
      <geom name="cylinder-3-geom" type="cylinder" size="0.0175 0.0175"
        rgba="0.4765625 0.68359375 0.29296875 1" mass="0.05" condim="6"
        solimp="0.998 0.998 0.001" solref="0.004 1" friction="3.0 0.1 0.01" density="0" priority="1"/>
    </body>

    <!-- ==================== LEFT ARM ==================== -->
    <body name="left_arm" pos="0.2525 0.31 0.76" childclass="yam">
      <geom class="visual" pos="0 0 -0.0006" quat="1 0 0 1" mesh="model2"/>
      <geom class="collision" size="0.033 0.01" pos="0.0 0.0 0.026" quat="1 0 0 0"/>
      <body name="left_link_1" pos="0 0 0.0631" quat="1 0 0 1">
        <inertial pos="-0.00192861 -0.00795735 0.0208176" quat="0.297851 0.642634 0.360045 0.607185" mass="0.12415"
          diaginertia="0.000180751 0.000145532 5.89179e-05"/>
        <joint name="left_joint1" range="-2.61799 3.05433" class="dm4340"/>
        <geom class="visual" pos="5.26159e-07 2.34355e-07 -0.0632" quat="1 0 0 0" mesh="model2__2"/>
        <body name="left_link_2" pos="2.5e-05 -0.02 0.0409" quat="1 1 1 1" gravcomp="1">
          <inertial pos="0.132008 2.10599e-06 0.000293073" quat="1 1 1 1" mass="1.24434"
            diaginertia="0.0121902 0.0121318 0.000683304"/>
          <joint name="left_joint2" range="0 3.66519" class="dm4340"/>
          <geom class="visual" pos="0.0199992 -0.1041 -2.44738e-05" quat="1 -1 -1 -1" mesh="model2__3"/>
          <geom class="visual" pos="0.0199992 -0.1041 -2.44738e-05" quat="1 -1 -1 -1" mesh="model2__4"/>
          <geom class="visual" pos="0.0199992 -0.1041 -2.44738e-05" quat="1 -1 -1 -1" mesh="model2__5" material="white"/>
          <geom class="collision" size="0.032 0.11" pos="0.13 0 0" quat="1 0 1 0"/>
          <geom class="collision" size="0.033 0.02" pos="0 0.0 0" quat="1 0 0 0"/>
          <geom class="collision" size="0.033 0.025" pos="0.265 0 0" quat="1 0 0 0"/>
          <body name="left_link_3" pos="0.264 0 0" quat="0 1 0 0" gravcomp="1">
            <inertial pos="-0.121816 -0.054846 -0.000111108" quat="1 1 1 1" mass="0.853698"
              diaginertia="0.00699732 0.00696112 0.000788244"/>
            <joint name="left_joint3" range="0 3.66519" class="dm4340"/>
            <geom class="visual" pos="-0.244001 0.104101 2.44738e-05" quat="1 1 1 -1" mesh="model2__6"/>
            <geom class="visual" pos="-0.244001 0.104101 2.44738e-05" quat="1 1 1 -1" mesh="model2__7"/>
            <geom class="visual" pos="-0.244001 0.104101 2.44738e-05" quat="1 1 1 -1" mesh="model2__8" material="white"/>
            <geom class="visual" pos="-0.244001 0.104101 2.44738e-05" quat="1 1 1 -1" mesh="model2__9"/>
            <geom class="collision" size="0.034 0.12" pos="-0.14 -0.06 0.0" quat="1 0 1 0"/>
            <geom class="collision" size="0.034 0.015" pos="-0.24 -0.06 0.0" quat="1 0 0 0"/>
            <body name="left_link_4" pos="-0.245 -0.06 0" quat="1 0 0 0" gravcomp="1">
              <inertial pos="-0.0769778 -0.0527104 0.000154878" quat="0.667 0.667 -0.236 -0.236" mass="0.463511"
                diaginertia="0.000791532 0.000744733 0.000282116"/>
              <joint name="left_joint4" range="-1.5708 1.5708" class="dm4310"/>
              <geom class="visual" pos="0.00100023 0.164101 2.44738e-05" quat="1 1 1 -1" mesh="model2__10"/>
              <geom class="collision" size="0.03 0.015" pos="-0.073 -0.06 0.0" quat="1 1 0 0"/>
              <body name="left_link_5" pos="-0.074 -0.0395 2.5e-05" quat="1 -1 1 1" gravcomp="1">
                <inertial pos="3.64861e-05 0.00025665 0.0353526" quat="1 0 0 0" mass="0.350962"
                  diaginertia="0.000197802 0.0001775 0.000147402"/>
                <joint name="left_joint5" range="-1.5708 1.5708" class="dm4310"/>
                <geom class="visual" pos="0 -0.0749971 0.203601" quat="1.32679e-06 1 0 0" mesh="model2__11"/>
                <geom class="collision" size="0.030 0.015" pos="0 0.025 0.0395" quat="1 1 0 0"/>
                <body name="left_link_6" pos="0 0.0353 0.0395" quat="1 -1 0 0" gravcomp="1">
                  <inertial pos="-0.000217767 7.37059e-05 0.0270545" quat="1 1 0 0" mass="0.367476"
                    diaginertia="0.000265958 0.000242686 0.000227409"/>
                  <joint name="left_joint6" range="-2.0944 2.0944" class="dm4310"/>
                  <geom class="visual" pos="0 -0.164101 -0.110597" quat="1 -1 0 0" mesh="model2__12"/>
                  <geom class="visual" pos="0 -0.164101 -0.110597" quat="1 -1 0 0" mesh="model2__13"/>
                  <geom class="collision" size="0.01 0.035" pos="0 0.039 0.052" quat="1 0 1 0"/>
                  <geom class="collision" size="0.030 0.005" pos="0 0.0 0.03" quat="1 0 0 1"/>
                  <geom class="collision" size="0.01 0.035" pos="0 -0.039 0.052" quat="1 0 1 0"/>
                  <site name="left_tcp_site" pos="0 0 0" quat="1 0 0 -1" size="0.005" rgba="1 0 0 1" group="4"/>
                  <site name="left_grasp_site" pos="0 0 0.1347" quat="1 0 0 -1" size="0.005" rgba="0 1 0 1" group="4"/>
                  <body name="left_camera_d405" pos="-0.0107 0.095 0.062" quat="0.906 0.423 0 0">
                    <geom type="mesh" contype="0" conaffinity="0" group="3" density="0.001" mass="0.001"
                      rgba="0 0 0 0" mesh="camera_d405"/>
                    <geom name="left_cam_col" type="sphere" size="0.02" pos="0 0 0"
                      group="3" rgba="0 0 1 0.0" mass="0.001"/>
                    <body name="left_camera_frame" pos="0.009 0 0" quat="0 0 0 1">
                      <camera name="left" pos="0 0 0" quat="0 1 0 0" fovy="58"/>
                    </body>
                  </body>
                  <body name="left_link_left_finger" pos="-0.037 0.0392 0.0605" quat="1 0 1 0" gravcomp="1">
                    <inertial pos="-0.0192995 -0.0365902 0.039774" quat="0.757351 0.568898 -0.3199 0.0" mass="0.118"
                      diaginertia="0.000159084 0.000154909 4.63655e-05"/>
                    <joint class="finger" name="left_left_finger" range="-0.00205 0.0475"/>
                    <geom class="visual" pos="0.171097 -0.203301 0.037" quat="1 -1 -1 -1" mesh="model2__14"/>
                    <geom class="visual" pos="0.171097 -0.203301 0.037" quat="1 -1 -1 -1" mesh="model2__15"/>
                    <body name="left_lf_rot" quat="1 -1 -1 1" pos="0.0 -0.0392 0.037" gravcomp="1">
                      <geom class="collision" size="0.01 0.03" pos="0.0 -0.02 0.012" quat="1 0 1 0"
                        rgba="0.381493 0.492734 0.780446 1"/>
                      <geom class="collision" size="0.01 0.02" pos="-0.02 -0.01 0.032" quat="1 0 2.5 0"
                        rgba="0.381493 0.492734 0.780446 1"/>
                      <body name="left_lf_down" quat="1 0 0 0" pos="-0.044 0.0 0.0" gravcomp="1">
                        <geom class="collision" size="0.01 0.01" pos="0.0 -0.020 0.012" quat="1 -0.1 0 0"
                          rgba="0.381493 0.492734 0.780446 1"/>
                        <geom class="collision" size="0.003 0.022" pos="0.005 -0.014 0.04" quat="1 -0.2 0 0"
                          rgba="0.381493 0.492734 0.780446 1"/>
                        <geom class="collision" size="0.003 0.022" pos="-0.005 -0.014 0.04" quat="1 -0.2 0 0"
                          rgba="0.381493 0.492734 0.780446 1"/>
                        <geom class="collision" type="box" size="0.006 0.002 0.04" friction="3.0 0.1 0.01" priority="2" solref="0.004 1" solimp="0.998 0.998 0.001" pos="0 -0.0024 0.046" quat="1 0 0 0"
                          rgba="0.381493 0.492734 0.780446 1"/>
                        <geom class="collision" type="box" size="0.006 0.002 0.039" friction="3.0 0.1 0.01" priority="2" solref="0.004 1" solimp="0.998 0.998 0.001" pos="0.027 -0.0024 0.053"
                          quat="1 0 2.5 0" rgba="0.381493 0.492734 0.780446 1"/>
                        <geom class="sphere_collision" pos="0.003  -0.0004 0.078"/>
                        <geom class="sphere_collision" pos="-0.003 -0.0004 0.078"/>
                        <geom class="sphere_collision" pos="0.003  -0.0004 0.07"/>
                        <geom class="sphere_collision" pos="-0.003 -0.0004 0.07"/>
                        <geom class="sphere_collision" pos="0.003  -0.0004 0.06"/>
                        <geom class="sphere_collision" pos="-0.003 -0.0004 0.06"/>
                      </body>
                    </body>
                  </body>
                  <body name="left_link_right_finger" pos="0.037 -0.0392 0.0605" quat="1 0 1 0" gravcomp="1">
                    <inertial pos="-0.0192995 0.0365902 -0.039774" quat="-0.757351 0.568898 -0.3199 0" mass="0.118"
                      diaginertia="0.000159084 0.000154909 4.63655e-05"/>
                    <joint class="finger" name="left_right_finger" range="-0.0475 0.00205"/>
                    <geom class="visual" pos="0.171097 -0.124901 -0.037" quat="1 -1 -1 -1" mesh="model2__16"/>
                    <geom class="visual" pos="0.171097 -0.124901 -0.037" quat="1 -1 -1 -1" mesh="model2__17"/>
                    <body name="left_rf_rot" quat="1 1 -1 -1" pos="0.0 0.0392 -0.037" gravcomp="1">
                      <geom class="collision" size="0.01 0.03" pos="0.0 -0.02 0.012" quat="1 0 1 0"
                        rgba="0.381493 0.492734 0.780446 1"/>
                      <geom class="collision" size="0.01 0.02" pos="0.02 -0.01 0.032" quat="1 0 -2.5 0"
                        rgba="0.381493 0.492734 0.780446 1"/>
                      <body name="left_rf_down" quat="1 0 0 0" pos="0.044 0.0 0.0" gravcomp="1">
                        <geom class="collision" size="0.01 0.01" pos="0.0 -0.020 0.012" quat="1 -0.1 0 0"
                          rgba="0.381493 0.492734 0.780446 1"/>
                        <geom class="collision" size="0.003 0.022" pos="0.005 -0.014 0.04" quat="1 -0.2 0 0"
                          rgba="0.381493 0.492734 0.780446 1"/>
                        <geom class="collision" size="0.003 0.022" pos="-0.005 -0.014 0.04" quat="1 -0.2 0 0"
                          rgba="0.381493 0.492734 0.780446 1"/>
                        <geom class="collision" type="box" size="0.006 0.002 0.04" friction="3.0 0.1 0.01" priority="2" solref="0.004 1" solimp="0.998 0.998 0.001" pos="0 -0.0024 0.046" quat="1 0 0 0"
                          rgba="0.381493 0.492734 0.780446 1"/>
                        <geom class="collision" type="box" size="0.006 0.002 0.039" friction="3.0 0.1 0.01" priority="2" solref="0.004 1" solimp="0.998 0.998 0.001" pos="-0.027 -0.0024 0.053"
                          quat="1 0 -2.5 0" rgba="0.381493 0.492734 0.780446 1"/>
                        <geom class="sphere_collision" pos="0.003  -0.0004 0.078"/>
                        <geom class="sphere_collision" pos="-0.003 -0.0004 0.078"/>
                        <geom class="sphere_collision" pos="0.003  -0.0004 0.07"/>
                        <geom class="sphere_collision" pos="-0.003 -0.0004 0.07"/>
                        <geom class="sphere_collision" pos="0.003  -0.0004 0.06"/>
                        <geom class="sphere_collision" pos="-0.003 -0.0004 0.06"/>
                      </body>
                    </body>
                  </body>
                </body>
              </body>
            </body>
          </body>
        </body>
      </body>
    </body>

    <!-- ==================== RIGHT ARM ==================== -->
    <body name="right_arm" pos="0.2525 -0.31 0.76" childclass="yam">
      <geom class="visual" pos="0 0 -0.0006" quat="1 0 0 1" mesh="model2"/>
      <geom class="collision" size="0.033 0.01" pos="0.0 0.0 0.026" quat="1 0 0 0"/>
      <body name="right_link_1" pos="0 0 0.0631" quat="1 0 0 1">
        <inertial pos="-0.00192861 -0.00795735 0.0208176" quat="0.297851 0.642634 0.360045 0.607185" mass="0.12415"
          diaginertia="0.000180751 0.000145532 5.89179e-05"/>
        <joint name="right_joint1" range="-2.61799 3.05433" class="dm4340"/>
        <geom class="visual" pos="5.26159e-07 2.34355e-07 -0.0632" quat="1 0 0 0" mesh="model2__2"/>
        <body name="right_link_2" pos="2.5e-05 -0.02 0.0409" quat="1 1 1 1" gravcomp="1">
          <inertial pos="0.132008 2.10599e-06 0.000293073" quat="1 1 1 1" mass="1.24434"
            diaginertia="0.0121902 0.0121318 0.000683304"/>
          <joint name="right_joint2" range="0 3.66519" class="dm4340"/>
          <geom class="visual" pos="0.0199992 -0.1041 -2.44738e-05" quat="1 -1 -1 -1" mesh="model2__3"/>
          <geom class="visual" pos="0.0199992 -0.1041 -2.44738e-05" quat="1 -1 -1 -1" mesh="model2__4"/>
          <geom class="visual" pos="0.0199992 -0.1041 -2.44738e-05" quat="1 -1 -1 -1" mesh="model2__5" material="white"/>
          <geom class="collision" size="0.032 0.11" pos="0.13 0 0" quat="1 0 1 0"/>
          <geom class="collision" size="0.033 0.02" pos="0 0.0 0" quat="1 0 0 0"/>
          <geom class="collision" size="0.033 0.025" pos="0.265 0 0" quat="1 0 0 0"/>
          <body name="right_link_3" pos="0.264 0 0" quat="0 1 0 0" gravcomp="1">
            <inertial pos="-0.121816 -0.054846 -0.000111108" quat="1 1 1 1" mass="0.853698"
              diaginertia="0.00699732 0.00696112 0.000788244"/>
            <joint name="right_joint3" range="0 3.66519" class="dm4340"/>
            <geom class="visual" pos="-0.244001 0.104101 2.44738e-05" quat="1 1 1 -1" mesh="model2__6"/>
            <geom class="visual" pos="-0.244001 0.104101 2.44738e-05" quat="1 1 1 -1" mesh="model2__7"/>
            <geom class="visual" pos="-0.244001 0.104101 2.44738e-05" quat="1 1 1 -1" mesh="model2__8" material="white"/>
            <geom class="visual" pos="-0.244001 0.104101 2.44738e-05" quat="1 1 1 -1" mesh="model2__9"/>
            <geom class="collision" size="0.034 0.12" pos="-0.14 -0.06 0.0" quat="1 0 1 0"/>
            <geom class="collision" size="0.034 0.015" pos="-0.24 -0.06 0.0" quat="1 0 0 0"/>
            <body name="right_link_4" pos="-0.245 -0.06 0" quat="1 0 0 0" gravcomp="1">
              <inertial pos="-0.0769778 -0.0527104 0.000154878" quat="0.667 0.667 -0.236 -0.236" mass="0.463511"
                diaginertia="0.000791532 0.000744733 0.000282116"/>
              <joint name="right_joint4" range="-1.5708 1.5708" class="dm4310"/>
              <geom class="visual" pos="0.00100023 0.164101 2.44738e-05" quat="1 1 1 -1" mesh="model2__10"/>
              <geom class="collision" size="0.03 0.015" pos="-0.073 -0.06 0.0" quat="1 1 0 0"/>
              <body name="right_link_5" pos="-0.074 -0.0395 2.5e-05" quat="1 -1 1 1" gravcomp="1">
                <inertial pos="3.64861e-05 0.00025665 0.0353526" quat="1 0 0 0" mass="0.350962"
                  diaginertia="0.000197802 0.0001775 0.000147402"/>
                <joint name="right_joint5" range="-1.5708 1.5708" class="dm4310"/>
                <geom class="visual" pos="0 -0.0749971 0.203601" quat="1.32679e-06 1 0 0" mesh="model2__11"/>
                <geom class="collision" size="0.030 0.015" pos="0 0.025 0.0395" quat="1 1 0 0"/>
                <body name="right_link_6" pos="0 0.0353 0.0395" quat="1 -1 0 0" gravcomp="1">
                  <inertial pos="-0.000217767 7.37059e-05 0.0270545" quat="1 1 0 0" mass="0.367476"
                    diaginertia="0.000265958 0.000242686 0.000227409"/>
                  <joint name="right_joint6" range="-2.0944 2.0944" class="dm4310"/>
                  <geom class="visual" pos="0 -0.164101 -0.110597" quat="1 -1 0 0" mesh="model2__12"/>
                  <geom class="visual" pos="0 -0.164101 -0.110597" quat="1 -1 0 0" mesh="model2__13"/>
                  <geom class="collision" size="0.01 0.035" pos="0 0.039 0.052" quat="1 0 1 0"/>
                  <geom class="collision" size="0.030 0.005" pos="0 0.0 0.03" quat="1 0 0 1"/>
                  <geom class="collision" size="0.01 0.035" pos="0 -0.039 0.052" quat="1 0 1 0"/>
                  <site name="right_tcp_site" pos="0 0 0" quat="1 0 0 -1" size="0.005" rgba="1 0 0 1" group="4"/>
                  <site name="right_grasp_site" pos="0 0 0.1347" quat="1 0 0 -1" size="0.005" rgba="0 1 0 1" group="4"/>
                  <body name="right_camera_d405" pos="-0.0107 0.095 0.062" quat="0.906 0.423 0 0">
                    <geom type="mesh" contype="0" conaffinity="0" group="3" density="0.001" mass="0.001"
                      rgba="0 0 0 0" mesh="camera_d405"/>
                    <geom name="right_cam_col" type="sphere" size="0.02" pos="0 0 0"
                      group="3" rgba="0 0 1 0.0" mass="0.001"/>
                    <body name="right_camera_frame" pos="0.009 0 0" quat="0 0 0 1">
                      <camera name="right" pos="0 0 0" quat="0 1 0 0" fovy="58"/>
                    </body>
                  </body>
                  <body name="right_link_left_finger" pos="-0.037 0.0392 0.0605" quat="1 0 1 0" gravcomp="1">
                    <inertial pos="-0.0192995 -0.0365902 0.039774" quat="0.757351 0.568898 -0.3199 0.0" mass="0.118"
                      diaginertia="0.000159084 0.000154909 4.63655e-05"/>
                    <joint class="finger" name="right_left_finger" range="-0.00205 0.0475"/>
                    <geom class="visual" pos="0.171097 -0.203301 0.037" quat="1 -1 -1 -1" mesh="model2__14"/>
                    <geom class="visual" pos="0.171097 -0.203301 0.037" quat="1 -1 -1 -1" mesh="model2__15"/>
                    <body name="right_lf_rot" quat="1 -1 -1 1" pos="0.0 -0.0392 0.037" gravcomp="1">
                      <geom class="collision" size="0.01 0.03" pos="0.0 -0.02 0.012" quat="1 0 1 0"
                        rgba="0.381493 0.492734 0.780446 1"/>
                      <geom class="collision" size="0.01 0.02" pos="-0.02 -0.01 0.032" quat="1 0 2.5 0"
                        rgba="0.381493 0.492734 0.780446 1"/>
                      <body name="right_lf_down" quat="1 0 0 0" pos="-0.044 0.0 0.0" gravcomp="1">
                        <geom class="collision" size="0.01 0.01" pos="0.0 -0.020 0.012" quat="1 -0.1 0 0"
                          rgba="0.381493 0.492734 0.780446 1"/>
                        <geom class="collision" size="0.003 0.022" pos="0.005 -0.014 0.04" quat="1 -0.2 0 0"
                          rgba="0.381493 0.492734 0.780446 1"/>
                        <geom class="collision" size="0.003 0.022" pos="-0.005 -0.014 0.04" quat="1 -0.2 0 0"
                          rgba="0.381493 0.492734 0.780446 1"/>
                        <geom class="collision" type="box" size="0.006 0.002 0.04" friction="3.0 0.1 0.01" priority="2" solref="0.004 1" solimp="0.998 0.998 0.001" pos="0 -0.0024 0.046" quat="1 0 0 0"
                          rgba="0.381493 0.492734 0.780446 1"/>
                        <geom class="collision" type="box" size="0.006 0.002 0.039" friction="3.0 0.1 0.01" priority="2" solref="0.004 1" solimp="0.998 0.998 0.001" pos="0.027 -0.0024 0.053"
                          quat="1 0 2.5 0" rgba="0.381493 0.492734 0.780446 1"/>
                        <geom class="sphere_collision" pos="0.003  -0.0004 0.078"/>
                        <geom class="sphere_collision" pos="-0.003 -0.0004 0.078"/>
                        <geom class="sphere_collision" pos="0.003  -0.0004 0.07"/>
                        <geom class="sphere_collision" pos="-0.003 -0.0004 0.07"/>
                        <geom class="sphere_collision" pos="0.003  -0.0004 0.06"/>
                        <geom class="sphere_collision" pos="-0.003 -0.0004 0.06"/>
                      </body>
                    </body>
                  </body>
                  <body name="right_link_right_finger" pos="0.037 -0.0392 0.0605" quat="1 0 1 0" gravcomp="1">
                    <inertial pos="-0.0192995 0.0365902 -0.039774" quat="-0.757351 0.568898 -0.3199 0" mass="0.118"
                      diaginertia="0.000159084 0.000154909 4.63655e-05"/>
                    <joint class="finger" name="right_right_finger" range="-0.0475 0.00205"/>
                    <geom class="visual" pos="0.171097 -0.124901 -0.037" quat="1 -1 -1 -1" mesh="model2__16"/>
                    <geom class="visual" pos="0.171097 -0.124901 -0.037" quat="1 -1 -1 -1" mesh="model2__17"/>
                    <body name="right_rf_rot" quat="1 1 -1 -1" pos="0.0 0.0392 -0.037" gravcomp="1">
                      <geom class="collision" size="0.01 0.03" pos="0.0 -0.02 0.012" quat="1 0 1 0"
                        rgba="0.381493 0.492734 0.780446 1"/>
                      <geom class="collision" size="0.01 0.02" pos="0.02 -0.01 0.032" quat="1 0 -2.5 0"
                        rgba="0.381493 0.492734 0.780446 1"/>
                      <body name="right_rf_down" quat="1 0 0 0" pos="0.044 0.0 0.0" gravcomp="1">
                        <geom class="collision" size="0.01 0.01" pos="0.0 -0.020 0.012" quat="1 -0.1 0 0"
                          rgba="0.381493 0.492734 0.780446 1"/>
                        <geom class="collision" size="0.003 0.022" pos="0.005 -0.014 0.04" quat="1 -0.2 0 0"
                          rgba="0.381493 0.492734 0.780446 1"/>
                        <geom class="collision" size="0.003 0.022" pos="-0.005 -0.014 0.04" quat="1 -0.2 0 0"
                          rgba="0.381493 0.492734 0.780446 1"/>
                        <geom class="collision" type="box" size="0.006 0.002 0.04" friction="3.0 0.1 0.01" priority="2" solref="0.004 1" solimp="0.998 0.998 0.001" pos="0 -0.0024 0.046" quat="1 0 0 0"
                          rgba="0.381493 0.492734 0.780446 1"/>
                        <geom class="collision" type="box" size="0.006 0.002 0.039" friction="3.0 0.1 0.01" priority="2" solref="0.004 1" solimp="0.998 0.998 0.001" pos="-0.027 -0.0024 0.053"
                          quat="1 0 -2.5 0" rgba="0.381493 0.492734 0.780446 1"/>
                        <geom class="sphere_collision" pos="0.003  -0.0004 0.078"/>
                        <geom class="sphere_collision" pos="-0.003 -0.0004 0.078"/>
                        <geom class="sphere_collision" pos="0.003  -0.0004 0.07"/>
                        <geom class="sphere_collision" pos="-0.003 -0.0004 0.07"/>
                        <geom class="sphere_collision" pos="0.003  -0.0004 0.06"/>
                        <geom class="sphere_collision" pos="-0.003 -0.0004 0.06"/>
                      </body>
                    </body>
                  </body>
                </body>
              </body>
            </body>
          </body>
        </body>
      </body>
    </body>
  </worldbody>

  <!-- Equality constraints: mirror left/right finger per arm -->
  <equality>
    <joint joint1="left_left_finger" joint2="left_right_finger" polycoef="0 -1 0 0 0"/>
    <joint joint1="right_left_finger" joint2="right_right_finger" polycoef="0 -1 0 0 0"/>
  </equality>

  <!-- Actuators: 14 total (7 per arm) -->
  <actuator>
    <!-- Left arm -->
    <position name="left_joint1" joint="left_joint1" class="dm4340"/>
    <position name="left_joint2" joint="left_joint2" class="dm4340"/>
    <position name="left_joint3" joint="left_joint3" class="dm4340"/>
    <position name="left_joint4" joint="left_joint4" class="dm4310" kp="20" kv=".5"/>
    <position name="left_joint5" joint="left_joint5" class="dm4310"/>
    <position name="left_joint6" joint="left_joint6" class="dm4310"/>
    <position class="finger" name="left_gripper" joint="left_left_finger"/>
    <!-- Right arm -->
    <position name="right_joint1" joint="right_joint1" class="dm4340"/>
    <position name="right_joint2" joint="right_joint2" class="dm4340"/>
    <position name="right_joint3" joint="right_joint3" class="dm4340"/>
    <position name="right_joint4" joint="right_joint4" class="dm4310" kp="20" kv=".5"/>
    <position name="right_joint5" joint="right_joint5" class="dm4310"/>
    <position name="right_joint6" joint="right_joint6" class="dm4310"/>
    <position class="finger" name="right_gripper" joint="right_left_finger"/>
  </actuator>

  <!-- Home keyframe -->
  <!-- qpos order: cylinder-1 (7), cylinder-2 (7), cylinder-3 (7), then 16 arm joints -->
  <!-- ball-sorting-toy is a fixed body — not in qpos -->
  <keyframe>
    <key name="home"
      qpos="0.45 0.12 0.78 0 0 1 0
            0.50 -0.15 0.78 0 0 1 0
            0.60 -0.08 0.78 0 0 1 0
            0 1.047 1.047 0 0 0 0 0  0 1.047 1.047 0 0 0 0 0"
      ctrl="0 1.047 1.047 0 0 0 0  0 1.047 1.047 0 0 0 0"/>
  </keyframe>
</mujoco>
