<mujoco model="yam_dishrack">
  <compiler angle="radian" meshdir="assets" texturedir="assets"/>

  <option integrator="implicitfast"/>

  <visual>
    <global azimuth="120" elevation="-20" offwidth="1920" offheight="1080"/>
    <quality shadowsize="8192" offsamples="16"/>
    <headlight ambient="0.40 0.40 0.40" diffuse="0.0 0.0 0.0" specular="0 0 0"/>
    <rgba haze="1.0 1.0 1.0 1"/>
  </visual>

  <default>
    <default class="yam">
      <position inheritrange="1"/>
      <joint frictionloss="0.1" axis="0 0 1"/>
      <default class="dm4340">
        <joint armature="0.032"/>
        <position kp="40" kv="2.5" forcerange="-28 28"/>
      </default>
      <default class="dm4310">
        <joint armature="0.0018"/>
        <position kp="10" kv="1" forcerange="-10 10"/>
      </default>
      <default class="visual">
        <geom type="mesh" contype="0" conaffinity="0" density="0" group="2" material="black"/>
      </default>
      <default class="collision">
        <geom group="3" type="capsule" friction="2.0 0.1 0.01" condim="6"/>
        <default class="sphere_collision">
          <geom size="0.0006 0 0" type="sphere" rgba="1 0 0 1" friction="4.0 0.1 0.01" condim="6" solimp="0.998 0.998 0.001" solref="0.004 1" priority="2"/>
        </default>
      </default>
      <default class="finger">
        <joint type="slide" armature="0.1" frictionloss="0.1"/>
        <position ctrlrange="0.0 0.0495" kp="400" kv="14" inheritrange="0"/>
      </default>
    </default>
    <default class="rack_visual">
      <geom group="2" type="mesh" contype="0" conaffinity="0"/>
    </default>
    <default class="rack_collision">
      <geom group="3" type="mesh" friction="0.5" density="0" solref="0.004 1" solimp="0.998 0.998 0.001"/>
    </default>
    <default class="plate_visual">
      <geom group="2" type="mesh" contype="0" conaffinity="0"/>
    </default>
    <default class="plate_collision">
      <geom group="3" type="mesh" density="0" friction="3.0 0.1 0.01" condim="6" solimp="0.998 0.998 0.001" solref="0.004 1" priority="1"/>
    </default>
  </default>

  <asset>
    <material name="black" rgba="0.30 0.30 0.30 1"/>
    <material name="white" rgba="0.9 0.9 0.9 1"/>

    <!-- Yam arm meshes -->
    <mesh file="i2rt_yam/assets/model2.stl"/>
    <mesh file="i2rt_yam/assets/model2__2.stl"/>
    <mesh file="i2rt_yam/assets/model2__3.stl"/>
    <mesh file="i2rt_yam/assets/model2__4.stl"/>
    <mesh file="i2rt_yam/assets/model2__5.stl"/>
    <mesh file="i2rt_yam/assets/model2__6.stl"/>
    <mesh file="i2rt_yam/assets/model2__7.stl"/>
    <mesh file="i2rt_yam/assets/model2__8.stl"/>
    <mesh file="i2rt_yam/assets/model2__9.stl"/>
    <mesh file="i2rt_yam/assets/model2__10.stl"/>
    <mesh file="i2rt_yam/assets/model2__11.stl"/>
    <mesh file="i2rt_yam/assets/model2__12.stl"/>
    <mesh file="i2rt_yam/assets/model2__13.stl"/>
    <mesh file="i2rt_yam/assets/model2__14.stl"/>
    <mesh file="i2rt_yam/assets/model2__15.stl"/>
    <mesh file="i2rt_yam/assets/model2__16.stl"/>
    <mesh file="i2rt_yam/assets/model2__17.stl"/>
    <mesh name="base_visual_gate" file="i2rt_yam/assets/base_visual_gate.stl"/>
    <mesh name="camera_d405" file="i2rt_yam/assets/d405.stl"/>

    <!-- Dishrack meshes -->
    <mesh name="rack_visual" file="dishrack/model.obj"/>
    <mesh name="rack_col_0" file="dishrack/model_collision_0.obj"/>
    <mesh name="rack_col_1" file="dishrack/model_collision_1.obj"/>
    <mesh name="rack_col_2" file="dishrack/model_collision_2.obj"/>
    <mesh name="rack_col_3" file="dishrack/model_collision_3.obj"/>
    <mesh name="rack_col_4" file="dishrack/model_collision_4.obj"/>
    <mesh name="rack_col_5" file="dishrack/model_collision_5.obj"/>
    <mesh name="rack_col_6" file="dishrack/model_collision_6.obj"/>
    <mesh name="rack_col_7" file="dishrack/model_collision_7.obj"/>
    <mesh name="rack_col_8" file="dishrack/model_collision_8.obj"/>
    <mesh name="rack_col_9" file="dishrack/model_collision_9.obj"/>
    <mesh name="rack_col_10" file="dishrack/model_collision_10.obj"/>
    <mesh name="rack_col_11" file="dishrack/model_collision_11.obj"/>
    <mesh name="rack_col_12" file="dishrack/model_collision_12.obj"/>
    <mesh name="rack_col_13" file="dishrack/model_collision_13.obj"/>
    <mesh name="rack_col_14" file="dishrack/model_collision_14.obj"/>
    <mesh name="rack_col_15" file="dishrack/model_collision_15.obj"/>
    <mesh name="rack_col_16" file="dishrack/model_collision_16.obj"/>
    <mesh name="rack_col_17" file="dishrack/model_collision_17.obj"/>
    <mesh name="rack_col_18" file="dishrack/model_collision_18.obj"/>
    <mesh name="rack_col_19" file="dishrack/model_collision_19.obj"/>
    <mesh name="rack_col_20" file="dishrack/model_collision_20.obj"/>
    <mesh name="rack_col_21" file="dishrack/model_collision_21.obj"/>
    <mesh name="rack_col_22" file="dishrack/model_collision_22.obj"/>
    <mesh name="rack_col_23" file="dishrack/model_collision_23.obj"/>
    <mesh name="rack_col_24" file="dishrack/model_collision_24.obj"/>
    <mesh name="rack_col_25" file="dishrack/model_collision_25.obj"/>
    <mesh name="rack_col_26" file="dishrack/model_collision_26.obj"/>
    <mesh name="rack_col_27" file="dishrack/model_collision_27.obj"/>
    <mesh name="rack_col_28" file="dishrack/model_collision_28.obj"/>
    <mesh name="rack_col_29" file="dishrack/model_collision_29.obj"/>
    <mesh name="rack_col_30" file="dishrack/model_collision_30.obj"/>
    <mesh name="rack_col_31" file="dishrack/model_collision_31.obj"/>
    <mesh name="rack_col_32" file="dishrack/model_collision_32.obj"/>
    <mesh name="rack_col_33" file="dishrack/model_collision_33.obj"/>
    <mesh name="rack_col_34" file="dishrack/model_collision_34.obj"/>
    <mesh name="rack_col_35" file="dishrack/model_collision_35.obj"/>
    <mesh name="rack_col_36" file="dishrack/model_collision_36.obj"/>
    <mesh name="rack_col_37" file="dishrack/model_collision_37.obj"/>
    <mesh name="rack_col_38" file="dishrack/model_collision_38.obj"/>
    <mesh name="rack_col_39" file="dishrack/model_collision_39.obj"/>
    <mesh name="rack_col_40" file="dishrack/model_collision_40.obj"/>
    <mesh name="rack_col_41" file="dishrack/model_collision_41.obj"/>
    <mesh name="rack_col_42" file="dishrack/model_collision_42.obj"/>
    <mesh name="rack_col_43" file="dishrack/model_collision_43.obj"/>
    <mesh name="rack_col_44" file="dishrack/model_collision_44.obj"/>
    <mesh name="rack_col_45" file="dishrack/model_collision_45.obj"/>
    <mesh name="rack_col_46" file="dishrack/model_collision_46.obj"/>
    <mesh name="rack_col_47" file="dishrack/model_collision_47.obj"/>
    <mesh name="rack_col_48" file="dishrack/model_collision_48.obj"/>
    <mesh name="rack_col_49" file="dishrack/model_collision_49.obj"/>
    <mesh name="rack_col_50" file="dishrack/model_collision_50.obj"/>
    <mesh name="rack_col_51" file="dishrack/model_collision_51.obj"/>
    <mesh name="rack_col_52" file="dishrack/model_collision_52.obj"/>
    <mesh name="rack_col_53" file="dishrack/model_collision_53.obj"/>
    <mesh name="rack_col_54" file="dishrack/model_collision_54.obj"/>
    <mesh name="rack_col_55" file="dishrack/model_collision_55.obj"/>
    <mesh name="rack_col_56" file="dishrack/model_collision_56.obj"/>
    <mesh name="rack_col_57" file="dishrack/model_collision_57.obj"/>
    <mesh name="rack_col_58" file="dishrack/model_collision_58.obj"/>
    <mesh name="rack_col_59" file="dishrack/model_collision_59.obj"/>
    <mesh name="rack_col_60" file="dishrack/model_collision_60.obj"/>
    <mesh name="rack_col_61" file="dishrack/model_collision_61.obj"/>
    <mesh name="rack_col_62" file="dishrack/model_collision_62.obj"/>
    <mesh name="rack_col_63" file="dishrack/model_collision_63.obj"/>
    <mesh name="rack_col_64" file="dishrack/model_collision_64.obj"/>
    <mesh name="rack_col_65" file="dishrack/model_collision_65.obj"/>
    <mesh name="rack_col_66" file="dishrack/model_collision_66.obj"/>
    <mesh name="rack_col_67" file="dishrack/model_collision_67.obj"/>
    <mesh name="rack_col_68" file="dishrack/model_collision_68.obj"/>
    <mesh name="rack_col_69" file="dishrack/model_collision_69.obj"/>
    <mesh name="rack_col_70" file="dishrack/model_collision_70.obj"/>
    <mesh name="rack_col_71" file="dishrack/model_collision_71.obj"/>
    <mesh name="rack_col_72" file="dishrack/model_collision_72.obj"/>
    <mesh name="rack_col_73" file="dishrack/model_collision_73.obj"/>
    <mesh name="rack_col_74" file="dishrack/model_collision_74.obj"/>
    <mesh name="rack_col_75" file="dishrack/model_collision_75.obj"/>
    <mesh name="rack_col_76" file="dishrack/model_collision_76.obj"/>
    <mesh name="rack_col_77" file="dishrack/model_collision_77.obj"/>
    <mesh name="rack_col_78" file="dishrack/model_collision_78.obj"/>
    <mesh name="rack_col_79" file="dishrack/model_collision_79.obj"/>
    <mesh name="rack_col_80" file="dishrack/model_collision_80.obj"/>
    <mesh name="rack_col_81" file="dishrack/model_collision_81.obj"/>
    <mesh name="rack_col_82" file="dishrack/model_collision_82.obj"/>
    <mesh name="rack_col_83" file="dishrack/model_collision_83.obj"/>
    <mesh name="rack_col_84" file="dishrack/model_collision_84.obj"/>
    <mesh name="rack_col_85" file="dishrack/model_collision_85.obj"/>
    <mesh name="rack_col_86" file="dishrack/model_collision_86.obj"/>
    <mesh name="rack_col_87" file="dishrack/model_collision_87.obj"/>
    <mesh name="rack_col_88" file="dishrack/model_collision_88.obj"/>
    <mesh name="rack_col_89" file="dishrack/model_collision_89.obj"/>
    <mesh name="rack_col_90" file="dishrack/model_collision_90.obj"/>
    <mesh name="rack_col_91" file="dishrack/model_collision_91.obj"/>
    <mesh name="rack_col_92" file="dishrack/model_collision_92.obj"/>
    <mesh name="rack_col_93" file="dishrack/model_collision_93.obj"/>
    <mesh name="rack_col_94" file="dishrack/model_collision_94.obj"/>
    <mesh name="rack_col_95" file="dishrack/model_collision_95.obj"/>
    <mesh name="rack_col_96" file="dishrack/model_collision_96.obj"/>
    <mesh name="rack_col_97" file="dishrack/model_collision_97.obj"/>
    <mesh name="rack_col_98" file="dishrack/model_collision_98.obj"/>
    <mesh name="rack_col_99" file="dishrack/model_collision_99.obj"/>
    <mesh name="rack_col_100" file="dishrack/model_collision_100.obj"/>
    <mesh name="rack_col_101" file="dishrack/model_collision_101.obj"/>
    <mesh name="rack_col_102" file="dishrack/model_collision_102.obj"/>
    <mesh name="rack_col_103" file="dishrack/model_collision_103.obj"/>
    <mesh name="rack_col_104" file="dishrack/model_collision_104.obj"/>
    <mesh name="rack_col_105" file="dishrack/model_collision_105.obj"/>
    <mesh name="rack_col_106" file="dishrack/model_collision_106.obj"/>
    <mesh name="rack_col_107" file="dishrack/model_collision_107.obj"/>
    <mesh name="rack_col_108" file="dishrack/model_collision_108.obj"/>
    <mesh name="rack_col_109" file="dishrack/model_collision_109.obj"/>
    <mesh name="rack_col_110" file="dishrack/model_collision_110.obj"/>
    <mesh name="rack_col_111" file="dishrack/model_collision_111.obj"/>
    <mesh name="rack_col_112" file="dishrack/model_collision_112.obj"/>
    <mesh name="rack_col_113" file="dishrack/model_collision_113.obj"/>
    <mesh name="rack_col_114" file="dishrack/model_collision_114.obj"/>
    <mesh name="rack_col_115" file="dishrack/model_collision_115.obj"/>
    <mesh name="rack_col_116" file="dishrack/model_collision_116.obj"/>
    <mesh name="rack_col_117" file="dishrack/model_collision_117.obj"/>
    <mesh name="rack_col_118" file="dishrack/model_collision_118.obj"/>
    <mesh name="rack_col_119" file="dishrack/model_collision_119.obj"/>
    <mesh name="rack_col_120" file="dishrack/model_collision_120.obj"/>
    <mesh name="rack_col_121" file="dishrack/model_collision_121.obj"/>
    <mesh name="rack_col_122" file="dishrack/model_collision_122.obj"/>
    <mesh name="rack_col_123" file="dishrack/model_collision_123.obj"/>
    <mesh name="rack_col_124" file="dishrack/model_collision_124.obj"/>
    <mesh name="rack_col_125" file="dishrack/model_collision_125.obj"/>
    <mesh name="rack_col_126" file="dishrack/model_collision_126.obj"/>
    <mesh name="rack_col_127" file="dishrack/model_collision_127.obj"/>
    <mesh name="rack_col_128" file="dishrack/model_collision_128.obj"/>
    <mesh name="rack_col_129" file="dishrack/model_collision_129.obj"/>
    <mesh name="rack_col_130" file="dishrack/model_collision_130.obj"/>
    <mesh name="rack_col_131" file="dishrack/model_collision_131.obj"/>
    <mesh name="rack_col_132" file="dishrack/model_collision_132.obj"/>
    <mesh name="rack_col_133" file="dishrack/model_collision_133.obj"/>
    <mesh name="rack_col_134" file="dishrack/model_collision_134.obj"/>
    <mesh name="rack_col_135" file="dishrack/model_collision_135.obj"/>
    <mesh name="rack_col_136" file="dishrack/model_collision_136.obj"/>
    <mesh name="rack_col_137" file="dishrack/model_collision_137.obj"/>
    <mesh name="rack_col_138" file="dishrack/model_collision_138.obj"/>
    <mesh name="rack_col_139" file="dishrack/model_collision_139.obj"/>
    <mesh name="rack_col_140" file="dishrack/model_collision_140.obj"/>
    <mesh name="rack_col_141" file="dishrack/model_collision_141.obj"/>
    <mesh name="rack_col_142" file="dishrack/model_collision_142.obj"/>
    <mesh name="rack_col_143" file="dishrack/model_collision_143.obj"/>
    <mesh name="rack_col_144" file="dishrack/model_collision_144.obj"/>
    <mesh name="rack_col_145" file="dishrack/model_collision_145.obj"/>
    <mesh name="rack_col_146" file="dishrack/model_collision_146.obj"/>
    <mesh name="rack_col_147" file="dishrack/model_collision_147.obj"/>
    <mesh name="rack_col_148" file="dishrack/model_collision_148.obj"/>
    <texture type="2d" name="rack_tex" file="dishrack/texture.png"/>
    <material name="rack_mat" texture="rack_tex" specular="0.5" shininess="0.5"/>

    <!-- Plate meshes -->
    <mesh name="plate_visual" file="plate/model.obj"/>
    <mesh name="plate_col_0" file="plate/model_collision_0.obj"/>
    <mesh name="plate_col_1" file="plate/model_collision_1.obj"/>
    <mesh name="plate_col_2" file="plate/model_collision_2.obj"/>
    <mesh name="plate_col_3" file="plate/model_collision_3.obj"/>
    <mesh name="plate_col_4" file="plate/model_collision_4.obj"/>
    <mesh name="plate_col_5" file="plate/model_collision_5.obj"/>
    <mesh name="plate_col_6" file="plate/model_collision_6.obj"/>
    <mesh name="plate_col_7" file="plate/model_collision_7.obj"/>
    <mesh name="plate_col_8" file="plate/model_collision_8.obj"/>
    <mesh name="plate_col_9" file="plate/model_collision_9.obj"/>
    <mesh name="plate_col_10" file="plate/model_collision_10.obj"/>
    <mesh name="plate_col_11" file="plate/model_collision_11.obj"/>
    <mesh name="plate_col_12" file="plate/model_collision_12.obj"/>
    <mesh name="plate_col_13" file="plate/model_collision_13.obj"/>
    <mesh name="plate_col_14" file="plate/model_collision_14.obj"/>
    <mesh name="plate_col_15" file="plate/model_collision_15.obj"/>
    <texture type="2d" name="plate_tex" file="plate/texture.png"/>
    <material name="plate_mat" texture="plate_tex" specular="0.5" shininess="0.5"/>

    <!-- Environment -->
    <texture type="skybox" builtin="gradient" rgb1="1.0 1.0 1.0" rgb2="0.98 0.98 0.98" width="512" height="3072"/>
    <texture type="2d" name="groundplane" builtin="checker" mark="edge"
      rgb1="0.55 0.55 0.55" rgb2="0.50 0.50 0.50" markrgb="0.6 0.6 0.6" width="300" height="300"/>
    <material name="groundplane" texture="groundplane" texuniform="true" texrepeat="5 5" reflectance="0.2"/>
  </asset>

  <worldbody>
    <!-- Lighting -->
    <light pos="0 0 1.5" dir="0 0 -1" directional="true"
      diffuse="0.30 0.30 0.30" specular="0.05 0.05 0.05"/>

    <!-- Floor -->
    <geom name="floor" size="0 0 0.05" type="plane" rgba="0.75 0.75 0.75 1"/>

    <!-- Gate/station structure (visual) -->
    <geom type="mesh" contype="0" conaffinity="0" group="2" density="0" rgba="0.60 0.62 0.68 1" mesh="base_visual_gate"/>
    <geom size="0.2975 0.65 0.375" pos="0 0 0.375" type="box" group="3" rgba="1 0 0 0.0"/>

    <!-- Gate collision bodies + top camera -->
    <body name="gate_collision" pos="0 0 0.75">
      <geom size="0.015 0.015 0.45" pos="0 0.575 0.45" type="box" group="3" rgba="1 0 0 0.0"/>
      <geom size="0.015 0.015 0.45" pos="0 -0.575 0.45" type="box" group="3" rgba="1 0 0 0.0"/>
      <geom size="0.015 0.015 0.59" pos="0 0 0.915" quat="0.707107 0.707107 0 0" type="box" group="3" rgba="1 0 0 0.0"/>
      <body name="top_bar_center" pos="0 0 0.915">
        <body name="top_camera_d405" pos="0.08600512 -0.009 0.03932053" quat="0.183012 0.683013 0.683013 0.183012">
          <geom type="mesh" contype="0" conaffinity="0" group="2" density="0.001" mass="0.001"
            rgba="0 0 0 0" mesh="camera_d405"/>
          <body name="top_camera_frame" pos="0.009 0 0" quat="0 0 0 1">
            <camera name="top" pos="0 0 0" quat="0 1 0 0" fovy="58"/>
          </body>
        </body>
      </body>
    </body>

    <!-- Enclosure walls -->
    <geom name="back_wall" type="box" size="0.005 0.65 1.0"
      pos="0.9 0 1.0" group="2"
      rgba="0.88 0.88 0.88 1"/>
    <geom name="left_wall" type="box" size="0.45 0.005 1.0"
      pos="0.45 0.65 1.0" group="2"
      rgba="0.88 0.88 0.88 1"/>
    <geom name="right_wall" type="box" size="0.45 0.005 1.0"
      pos="0.45 -0.65 1.0" group="2"
      rgba="0.88 0.88 0.88 1"/>

    <!-- Play table -->
    
    <!-- Side cameras on cage walls -->
    
    <!-- Overhead camera -->
    <body name="overhead_camera" pos="0.55 0.0 1.6">
      <camera name="overhead" pos="0 0 0" quat="0.707 0 0 -0.707" fovy="60"/>
    </body>

    <body name="left_side_camera" pos="0.5 0.55 1.05" euler="-1.3 0 3.14159">
      <camera name="left_side" pos="0 0 0" fovy="70"/>
    </body>
    <body name="right_side_camera" pos="0.5 -0.55 1.05" euler="1.3 0 0">
      <camera name="right_side" pos="0 0 0" fovy="70"/>
    </body>

    <body name="play_table">
      <geom size="0.2975 0.65 0.005" pos="0.6 0 0.745" type="box" group="2" contype="0" conaffinity="0" rgba="0.92 0.92 0.92 1"/>
    </body>
    <geom name="table_plane" type="plane" size="0.2975 0.65 0.01" pos="0.6 0 0.75" rgba="0 0 0 0" group="3"/>

    <!-- ==================== TASK OBJECTS ==================== -->

    <!-- Dishrack on the table (right side) -->
    <body name="dishrack" pos="0.62 -0.24 0.75">
      <geom material="rack_mat" mesh="rack_visual" class="rack_visual" mass="0.5"/>
      <geom mesh="rack_col_0" class="rack_collision"/>
      <geom mesh="rack_col_1" class="rack_collision"/>
      <geom mesh="rack_col_2" class="rack_collision"/>
      <geom mesh="rack_col_3" class="rack_collision"/>
      <geom mesh="rack_col_4" class="rack_collision"/>
      <geom mesh="rack_col_5" class="rack_collision"/>
      <geom mesh="rack_col_6" class="rack_collision"/>
      <geom mesh="rack_col_7" class="rack_collision"/>
      <geom mesh="rack_col_8" class="rack_collision"/>
      <geom mesh="rack_col_9" class="rack_collision"/>
      <geom mesh="rack_col_10" class="rack_collision"/>
      <geom mesh="rack_col_11" class="rack_collision"/>
      <geom mesh="rack_col_12" class="rack_collision"/>
      <geom mesh="rack_col_13" class="rack_collision"/>
      <geom mesh="rack_col_14" class="rack_collision"/>
      <geom mesh="rack_col_15" class="rack_collision"/>
      <geom mesh="rack_col_16" class="rack_collision"/>
      <geom mesh="rack_col_17" class="rack_collision"/>
      <geom mesh="rack_col_18" class="rack_collision"/>
      <geom mesh="rack_col_19" class="rack_collision"/>
      <geom mesh="rack_col_20" class="rack_collision"/>
      <geom mesh="rack_col_21" class="rack_collision"/>
      <geom mesh="rack_col_22" class="rack_collision"/>
      <geom mesh="rack_col_23" class="rack_collision"/>
      <geom mesh="rack_col_24" class="rack_collision"/>
      <geom mesh="rack_col_25" class="rack_collision"/>
      <geom mesh="rack_col_26" class="rack_collision"/>
      <geom mesh="rack_col_27" class="rack_collision"/>
      <geom mesh="rack_col_28" class="rack_collision"/>
      <geom mesh="rack_col_29" class="rack_collision"/>
      <geom mesh="rack_col_30" class="rack_collision"/>
      <geom mesh="rack_col_31" class="rack_collision"/>
      <geom mesh="rack_col_32" class="rack_collision"/>
      <geom mesh="rack_col_33" class="rack_collision"/>
      <geom mesh="rack_col_34" class="rack_collision"/>
      <geom mesh="rack_col_35" class="rack_collision"/>
      <geom mesh="rack_col_36" class="rack_collision"/>
      <geom mesh="rack_col_37" class="rack_collision"/>
      <geom mesh="rack_col_38" class="rack_collision"/>
      <geom mesh="rack_col_39" class="rack_collision"/>
      <geom mesh="rack_col_40" class="rack_collision"/>
      <geom mesh="rack_col_41" class="rack_collision"/>
      <geom mesh="rack_col_42" class="rack_collision"/>
      <geom mesh="rack_col_43" class="rack_collision"/>
      <geom mesh="rack_col_44" class="rack_collision"/>
      <geom mesh="rack_col_45" class="rack_collision"/>
      <geom mesh="rack_col_46" class="rack_collision"/>
      <geom mesh="rack_col_47" class="rack_collision"/>
      <geom mesh="rack_col_48" class="rack_collision"/>
      <geom mesh="rack_col_49" class="rack_collision"/>
      <geom mesh="rack_col_50" class="rack_collision"/>
      <geom mesh="rack_col_51" class="rack_collision"/>
      <geom mesh="rack_col_52" class="rack_collision"/>
      <geom mesh="rack_col_53" class="rack_collision"/>
      <geom mesh="rack_col_54" class="rack_collision"/>
      <geom mesh="rack_col_55" class="rack_collision"/>
      <geom mesh="rack_col_56" class="rack_collision"/>
      <geom mesh="rack_col_57" class="rack_collision"/>
      <geom mesh="rack_col_58" class="rack_collision"/>
      <geom mesh="rack_col_59" class="rack_collision"/>
      <geom mesh="rack_col_60" class="rack_collision"/>
      <geom mesh="rack_col_61" class="rack_collision"/>
      <geom mesh="rack_col_62" class="rack_collision"/>
      <geom mesh="rack_col_63" class="rack_collision"/>
      <geom mesh="rack_col_64" class="rack_collision"/>
      <geom mesh="rack_col_65" class="rack_collision"/>
      <geom mesh="rack_col_66" class="rack_collision"/>
      <geom mesh="rack_col_67" class="rack_collision"/>
      <geom mesh="rack_col_68" class="rack_collision"/>
      <geom mesh="rack_col_69" class="rack_collision"/>
      <geom mesh="rack_col_70" class="rack_collision"/>
      <geom mesh="rack_col_71" class="rack_collision"/>
      <geom mesh="rack_col_72" class="rack_collision"/>
      <geom mesh="rack_col_73" class="rack_collision"/>
      <geom mesh="rack_col_74" class="rack_collision"/>
      <geom mesh="rack_col_75" class="rack_collision"/>
      <geom mesh="rack_col_76" class="rack_collision"/>
      <geom mesh="rack_col_77" class="rack_collision"/>
      <geom mesh="rack_col_78" class="rack_collision"/>
      <geom mesh="rack_col_79" class="rack_collision"/>
      <geom mesh="rack_col_80" class="rack_collision"/>
      <geom mesh="rack_col_81" class="rack_collision"/>
      <geom mesh="rack_col_82" class="rack_collision"/>
      <geom mesh="rack_col_83" class="rack_collision"/>
      <geom mesh="rack_col_84" class="rack_collision"/>
      <geom mesh="rack_col_85" class="rack_collision"/>
      <geom mesh="rack_col_86" class="rack_collision"/>
      <geom mesh="rack_col_87" class="rack_collision"/>
      <geom mesh="rack_col_88" class="rack_collision"/>
      <geom mesh="rack_col_89" class="rack_collision"/>
      <geom mesh="rack_col_90" class="rack_collision"/>
      <geom mesh="rack_col_91" class="rack_collision"/>
      <geom mesh="rack_col_92" class="rack_collision"/>
      <geom mesh="rack_col_93" class="rack_collision"/>
      <geom mesh="rack_col_94" class="rack_collision"/>
      <geom mesh="rack_col_95" class="rack_collision"/>
      <geom mesh="rack_col_96" class="rack_collision"/>
      <geom mesh="rack_col_97" class="rack_collision"/>
      <geom mesh="rack_col_98" class="rack_collision"/>
      <geom mesh="rack_col_99" class="rack_collision"/>
      <geom mesh="rack_col_100" class="rack_collision"/>
      <geom mesh="rack_col_101" class="rack_collision"/>
      <geom mesh="rack_col_102" class="rack_collision"/>
      <geom mesh="rack_col_103" class="rack_collision"/>
      <geom mesh="rack_col_104" class="rack_collision"/>
      <geom mesh="rack_col_105" class="rack_collision"/>
      <geom mesh="rack_col_106" class="rack_collision"/>
      <geom mesh="rack_col_107" class="rack_collision"/>
      <geom mesh="rack_col_108" class="rack_collision"/>
      <geom mesh="rack_col_109" class="rack_collision"/>
      <geom mesh="rack_col_110" class="rack_collision"/>
      <geom mesh="rack_col_111" class="rack_collision"/>
      <geom mesh="rack_col_112" class="rack_collision"/>
      <geom mesh="rack_col_113" class="rack_collision"/>
      <geom mesh="rack_col_114" class="rack_collision"/>
      <geom mesh="rack_col_115" class="rack_collision"/>
      <geom mesh="rack_col_116" class="rack_collision"/>
      <geom mesh="rack_col_117" class="rack_collision"/>
      <geom mesh="rack_col_118" class="rack_collision"/>
      <geom mesh="rack_col_119" class="rack_collision"/>
      <geom mesh="rack_col_120" class="rack_collision"/>
      <geom mesh="rack_col_121" class="rack_collision"/>
      <geom mesh="rack_col_122" class="rack_collision"/>
      <geom mesh="rack_col_123" class="rack_collision"/>
      <geom mesh="rack_col_124" class="rack_collision"/>
      <geom mesh="rack_col_125" class="rack_collision"/>
      <geom mesh="rack_col_126" class="rack_collision"/>
      <geom mesh="rack_col_127" class="rack_collision"/>
      <geom mesh="rack_col_128" class="rack_collision"/>
      <geom mesh="rack_col_129" class="rack_collision"/>
      <geom mesh="rack_col_130" class="rack_collision"/>
      <geom mesh="rack_col_131" class="rack_collision"/>
      <geom mesh="rack_col_132" class="rack_collision"/>
      <geom mesh="rack_col_133" class="rack_collision"/>
      <geom mesh="rack_col_134" class="rack_collision"/>
      <geom mesh="rack_col_135" class="rack_collision"/>
      <geom mesh="rack_col_136" class="rack_collision"/>
      <geom mesh="rack_col_137" class="rack_collision"/>
      <geom mesh="rack_col_138" class="rack_collision"/>
      <geom mesh="rack_col_139" class="rack_collision"/>
      <geom mesh="rack_col_140" class="rack_collision"/>
      <geom mesh="rack_col_141" class="rack_collision"/>
      <geom mesh="rack_col_142" class="rack_collision"/>
      <geom mesh="rack_col_143" class="rack_collision"/>
      <geom mesh="rack_col_144" class="rack_collision"/>
      <geom mesh="rack_col_145" class="rack_collision"/>
      <geom mesh="rack_col_146" class="rack_collision"/>
      <geom mesh="rack_col_147" class="rack_collision"/>
      <geom mesh="rack_col_148" class="rack_collision"/>
    </body>

    <!-- Plate on the table (left side) -->
    <body name="plate" pos="0.50 0.20 0.76">
      <freejoint name="plate_joint"/>
      <geom material="plate_mat" mesh="plate_visual" class="plate_visual" mass="0.075"/>
      <geom mesh="plate_col_0" class="plate_collision"/>
      <geom mesh="plate_col_1" class="plate_collision"/>
      <geom mesh="plate_col_2" class="plate_collision"/>
      <geom mesh="plate_col_3" class="plate_collision"/>
      <geom mesh="plate_col_4" class="plate_collision"/>
      <geom mesh="plate_col_5" class="plate_collision"/>
      <geom mesh="plate_col_6" class="plate_collision"/>
      <geom mesh="plate_col_7" class="plate_collision"/>
      <geom mesh="plate_col_8" class="plate_collision"/>
      <geom mesh="plate_col_9" class="plate_collision"/>
      <geom mesh="plate_col_10" class="plate_collision"/>
      <geom mesh="plate_col_11" class="plate_collision"/>
      <geom mesh="plate_col_12" class="plate_collision"/>
      <geom mesh="plate_col_13" class="plate_collision"/>
      <geom mesh="plate_col_14" class="plate_collision"/>
      <geom mesh="plate_col_15" class="plate_collision"/>
    </body>

    <!-- ==================== LEFT ARM ==================== -->
    <body name="left_arm" pos="0.2525 0.31 0.76" childclass="yam">
      <geom class="visual" pos="0 0 -0.0006" quat="1 0 0 1" mesh="model2"/>
      <geom class="collision" size="0.033 0.01" pos="0.0 0.0 0.026" quat="1 0 0 0"/>
      <body name="left_link_1" pos="0 0 0.0631" quat="1 0 0 1">
        <inertial pos="-0.00192861 -0.00795735 0.0208176" quat="0.297851 0.642634 0.360045 0.607185" mass="0.12415"
          diaginertia="0.000180751 0.000145532 5.89179e-05"/>
        <joint name="left_joint1" range="-2.61799 3.05433" class="dm4340"/>
        <geom class="visual" pos="5.26159e-07 2.34355e-07 -0.0632" quat="1 0 0 0" mesh="model2__2"/>
        <body name="left_link_2" pos="2.5e-05 -0.02 0.0409" quat="1 1 1 1" gravcomp="1">
          <inertial pos="0.132008 2.10599e-06 0.000293073" quat="1 1 1 1" mass="1.24434"
            diaginertia="0.0121902 0.0121318 0.000683304"/>
          <joint name="left_joint2" range="0 3.66519" class="dm4340"/>
          <geom class="visual" pos="0.0199992 -0.1041 -2.44738e-05" quat="1 -1 -1 -1" mesh="model2__3"/>
          <geom class="visual" pos="0.0199992 -0.1041 -2.44738e-05" quat="1 -1 -1 -1" mesh="model2__4"/>
          <geom class="visual" pos="0.0199992 -0.1041 -2.44738e-05" quat="1 -1 -1 -1" mesh="model2__5" material="white"/>
          <geom class="collision" size="0.032 0.11" pos="0.13 0 0" quat="1 0 1 0"/>
          <geom class="collision" size="0.033 0.02" pos="0 0.0 0" quat="1 0 0 0"/>
          <geom class="collision" size="0.033 0.025" pos="0.265 0 0" quat="1 0 0 0"/>
          <body name="left_link_3" pos="0.264 0 0" quat="0 1 0 0" gravcomp="1">
            <inertial pos="-0.121816 -0.054846 -0.000111108" quat="1 1 1 1" mass="0.853698"
              diaginertia="0.00699732 0.00696112 0.000788244"/>
            <joint name="left_joint3" range="0 3.66519" class="dm4340"/>
            <geom class="visual" pos="-0.244001 0.104101 2.44738e-05" quat="1 1 1 -1" mesh="model2__6"/>
            <geom class="visual" pos="-0.244001 0.104101 2.44738e-05" quat="1 1 1 -1" mesh="model2__7"/>
            <geom class="visual" pos="-0.244001 0.104101 2.44738e-05" quat="1 1 1 -1" mesh="model2__8" material="white"/>
            <geom class="visual" pos="-0.244001 0.104101 2.44738e-05" quat="1 1 1 -1" mesh="model2__9"/>
            <geom class="collision" size="0.034 0.12" pos="-0.14 -0.06 0.0" quat="1 0 1 0"/>
            <geom class="collision" size="0.034 0.015" pos="-0.24 -0.06 0.0" quat="1 0 0 0"/>
            <body name="left_link_4" pos="-0.245 -0.06 0" quat="1 0 0 0" gravcomp="1">
              <inertial pos="-0.0769778 -0.0527104 0.000154878" quat="0.667 0.667 -0.236 -0.236" mass="0.463511"
                diaginertia="0.000791532 0.000744733 0.000282116"/>
              <joint name="left_joint4" range="-1.5708 1.5708" class="dm4310"/>
              <geom class="visual" pos="0.00100023 0.164101 2.44738e-05" quat="1 1 1 -1" mesh="model2__10"/>
              <geom class="collision" size="0.03 0.015" pos="-0.073 -0.06 0.0" quat="1 1 0 0"/>
              <body name="left_link_5" pos="-0.074 -0.0395 2.5e-05" quat="1 -1 1 1" gravcomp="1">
                <inertial pos="3.64861e-05 0.00025665 0.0353526" quat="1 0 0 0" mass="0.350962"
                  diaginertia="0.000197802 0.0001775 0.000147402"/>
                <joint name="left_joint5" range="-1.5708 1.5708" class="dm4310"/>
                <geom class="visual" pos="0 -0.0749971 0.203601" quat="1.32679e-06 1 0 0" mesh="model2__11"/>
                <geom class="collision" size="0.030 0.015" pos="0 0.025 0.0395" quat="1 1 0 0"/>
                <body name="left_link_6" pos="0 0.0353 0.0395" quat="1 -1 0 0" gravcomp="1">
                  <inertial pos="-0.000217767 7.37059e-05 0.0270545" quat="1 1 0 0" mass="0.367476"
                    diaginertia="0.000265958 0.000242686 0.000227409"/>
                  <joint name="left_joint6" range="-2.0944 2.0944" class="dm4310"/>
                  <geom class="visual" pos="0 -0.164101 -0.110597" quat="1 -1 0 0" mesh="model2__12"/>
                  <geom class="visual" pos="0 -0.164101 -0.110597" quat="1 -1 0 0" mesh="model2__13"/>
                  <geom class="collision" size="0.01 0.035" pos="0 0.039 0.052" quat="1 0 1 0"/>
                  <geom class="collision" size="0.030 0.005" pos="0 0.0 0.03" quat="1 0 0 1"/>
                  <geom class="collision" size="0.01 0.035" pos="0 -0.039 0.052" quat="1 0 1 0"/>
                  <site name="left_tcp_site" pos="0 0 0" quat="1 0 0 -1" size="0.005" rgba="1 0 0 1" group="4"/>
                  <site name="left_grasp_site" pos="0 0 0.1347" quat="1 0 0 -1" size="0.005" rgba="0 1 0 1" group="4"/>
                  <body name="left_camera_d405" pos="-0.0107 0.095 0.062" quat="0.906 0.423 0 0">
                    <geom type="mesh" contype="0" conaffinity="0" group="3" density="0.001" mass="0.001"
                      rgba="0 0 0 0" mesh="camera_d405"/>
                    <geom name="left_cam_col" type="sphere" size="0.02" pos="0 0 0"
                      group="3" rgba="0 0 1 0.0" mass="0.001"/>
                    <body name="left_camera_frame" pos="0.009 0 0" quat="0 0 0 1">
                      <camera name="left" pos="0 0 0" quat="0 1 0 0" fovy="58"/>
                    </body>
                  </body>
                  <body name="left_link_left_finger" pos="-0.037 0.0392 0.0605" quat="1 0 1 0" gravcomp="1">
                    <inertial pos="-0.0192995 -0.0365902 0.039774" quat="0.757351 0.568898 -0.3199 0.0" mass="0.118"
                      diaginertia="0.000159084 0.000154909 4.63655e-05"/>
                    <joint class="finger" name="left_left_finger" range="-0.00205 0.0475"/>
                    <geom class="visual" pos="0.171097 -0.203301 0.037" quat="1 -1 -1 -1" mesh="model2__14"/>
                    <geom class="visual" pos="0.171097 -0.203301 0.037" quat="1 -1 -1 -1" mesh="model2__15"/>
                    <body name="left_lf_rot" quat="1 -1 -1 1" pos="0.0 -0.0392 0.037" gravcomp="1">
                      <geom class="collision" size="0.01 0.03" pos="0.0 -0.02 0.012" quat="1 0 1 0"
                        rgba="0.381493 0.492734 0.780446 1"/>
                      <geom class="collision" size="0.01 0.02" pos="-0.02 -0.01 0.032" quat="1 0 2.5 0"
                        rgba="0.381493 0.492734 0.780446 1"/>
                      <body name="left_lf_down" quat="1 0 0 0" pos="-0.044 0.0 0.0" gravcomp="1">
                        <geom class="collision" size="0.01 0.01" pos="0.0 -0.020 0.012" quat="1 -0.1 0 0"
                          rgba="0.381493 0.492734 0.780446 1"/>
                        <geom class="collision" size="0.003 0.022" pos="0.005 -0.014 0.04" quat="1 -0.2 0 0"
                          rgba="0.381493 0.492734 0.780446 1"/>
                        <geom class="collision" size="0.003 0.022" pos="-0.005 -0.014 0.04" quat="1 -0.2 0 0"
                          rgba="0.381493 0.492734 0.780446 1"/>
                        <geom class="collision" type="box" size="0.006 0.002 0.04" friction="3.0 0.1 0.01" priority="2" solref="0.004 1" solimp="0.998 0.998 0.001" pos="0 -0.0024 0.046" quat="1 0 0 0"
                          rgba="0.381493 0.492734 0.780446 1"/>
                        <geom class="collision" type="box" size="0.006 0.002 0.039" friction="3.0 0.1 0.01" priority="2" solref="0.004 1" solimp="0.998 0.998 0.001" pos="0.027 -0.0024 0.053"
                          quat="1 0 2.5 0" rgba="0.381493 0.492734 0.780446 1"/>
                        <geom class="sphere_collision" pos="0.003  -0.0004 0.078"/>
                        <geom class="sphere_collision" pos="-0.003 -0.0004 0.078"/>
                        <geom class="sphere_collision" pos="0.003  -0.0004 0.07"/>
                        <geom class="sphere_collision" pos="-0.003 -0.0004 0.07"/>
                        <geom class="sphere_collision" pos="0.003  -0.0004 0.06"/>
                        <geom class="sphere_collision" pos="-0.003 -0.0004 0.06"/>
                      </body>
                    </body>
                  </body>
                  <body name="left_link_right_finger" pos="0.037 -0.0392 0.0605" quat="1 0 1 0" gravcomp="1">
                    <inertial pos="-0.0192995 0.0365902 -0.039774" quat="-0.757351 0.568898 -0.3199 0" mass="0.118"
                      diaginertia="0.000159084 0.000154909 4.63655e-05"/>
                    <joint class="finger" name="left_right_finger" range="-0.0475 0.00205"/>
                    <geom class="visual" pos="0.171097 -0.124901 -0.037" quat="1 -1 -1 -1" mesh="model2__16"/>
                    <geom class="visual" pos="0.171097 -0.124901 -0.037" quat="1 -1 -1 -1" mesh="model2__17"/>
                    <body name="left_rf_rot" quat="1 1 -1 -1" pos="0.0 0.0392 -0.037" gravcomp="1">
                      <geom class="collision" size="0.01 0.03" pos="0.0 -0.02 0.012" quat="1 0 1 0"
                        rgba="0.381493 0.492734 0.780446 1"/>
                      <geom class="collision" size="0.01 0.02" pos="0.02 -0.01 0.032" quat="1 0 -2.5 0"
                        rgba="0.381493 0.492734 0.780446 1"/>
                      <body name="left_rf_down" quat="1 0 0 0" pos="0.044 0.0 0.0" gravcomp="1">
                        <geom class="collision" size="0.01 0.01" pos="0.0 -0.020 0.012" quat="1 -0.1 0 0"
                          rgba="0.381493 0.492734 0.780446 1"/>
                        <geom class="collision" size="0.003 0.022" pos="0.005 -0.014 0.04" quat="1 -0.2 0 0"
                          rgba="0.381493 0.492734 0.780446 1"/>
                        <geom class="collision" size="0.003 0.022" pos="-0.005 -0.014 0.04" quat="1 -0.2 0 0"
                          rgba="0.381493 0.492734 0.780446 1"/>
                        <geom class="collision" type="box" size="0.006 0.002 0.04" friction="3.0 0.1 0.01" priority="2" solref="0.004 1" solimp="0.998 0.998 0.001" pos="0 -0.0024 0.046" quat="1 0 0 0"
                          rgba="0.381493 0.492734 0.780446 1"/>
                        <geom class="collision" type="box" size="0.006 0.002 0.039" friction="3.0 0.1 0.01" priority="2" solref="0.004 1" solimp="0.998 0.998 0.001" pos="-0.027 -0.0024 0.053"
                          quat="1 0 -2.5 0" rgba="0.381493 0.492734 0.780446 1"/>
                        <geom class="sphere_collision" pos="0.003  -0.0004 0.078"/>
                        <geom class="sphere_collision" pos="-0.003 -0.0004 0.078"/>
                        <geom class="sphere_collision" pos="0.003  -0.0004 0.07"/>
                        <geom class="sphere_collision" pos="-0.003 -0.0004 0.07"/>
                        <geom class="sphere_collision" pos="0.003  -0.0004 0.06"/>
                        <geom class="sphere_collision" pos="-0.003 -0.0004 0.06"/>
                      </body>
                    </body>
                  </body>
                </body>
              </body>
            </body>
          </body>
        </body>
      </body>
    </body>

    <!-- ==================== RIGHT ARM ==================== -->
    <body name="right_arm" pos="0.2525 -0.31 0.76" childclass="yam">
      <geom class="visual" pos="0 0 -0.0006" quat="1 0 0 1" mesh="model2"/>
      <geom class="collision" size="0.033 0.01" pos="0.0 0.0 0.026" quat="1 0 0 0"/>
      <body name="right_link_1" pos="0 0 0.0631" quat="1 0 0 1">
        <inertial pos="-0.00192861 -0.00795735 0.0208176" quat="0.297851 0.642634 0.360045 0.607185" mass="0.12415"
          diaginertia="0.000180751 0.000145532 5.89179e-05"/>
        <joint name="right_joint1" range="-2.61799 3.05433" class="dm4340"/>
        <geom class="visual" pos="5.26159e-07 2.34355e-07 -0.0632" quat="1 0 0 0" mesh="model2__2"/>
        <body name="right_link_2" pos="2.5e-05 -0.02 0.0409" quat="1 1 1 1" gravcomp="1">
          <inertial pos="0.132008 2.10599e-06 0.000293073" quat="1 1 1 1" mass="1.24434"
            diaginertia="0.0121902 0.0121318 0.000683304"/>
          <joint name="right_joint2" range="0 3.66519" class="dm4340"/>
          <geom class="visual" pos="0.0199992 -0.1041 -2.44738e-05" quat="1 -1 -1 -1" mesh="model2__3"/>
          <geom class="visual" pos="0.0199992 -0.1041 -2.44738e-05" quat="1 -1 -1 -1" mesh="model2__4"/>
          <geom class="visual" pos="0.0199992 -0.1041 -2.44738e-05" quat="1 -1 -1 -1" mesh="model2__5" material="white"/>
          <geom class="collision" size="0.032 0.11" pos="0.13 0 0" quat="1 0 1 0"/>
          <geom class="collision" size="0.033 0.02" pos="0 0.0 0" quat="1 0 0 0"/>
          <geom class="collision" size="0.033 0.025" pos="0.265 0 0" quat="1 0 0 0"/>
          <body name="right_link_3" pos="0.264 0 0" quat="0 1 0 0" gravcomp="1">
            <inertial pos="-0.121816 -0.054846 -0.000111108" quat="1 1 1 1" mass="0.853698"
              diaginertia="0.00699732 0.00696112 0.000788244"/>
            <joint name="right_joint3" range="0 3.66519" class="dm4340"/>
            <geom class="visual" pos="-0.244001 0.104101 2.44738e-05" quat="1 1 1 -1" mesh="model2__6"/>
            <geom class="visual" pos="-0.244001 0.104101 2.44738e-05" quat="1 1 1 -1" mesh="model2__7"/>
            <geom class="visual" pos="-0.244001 0.104101 2.44738e-05" quat="1 1 1 -1" mesh="model2__8" material="white"/>
            <geom class="visual" pos="-0.244001 0.104101 2.44738e-05" quat="1 1 1 -1" mesh="model2__9"/>
            <geom class="collision" size="0.034 0.12" pos="-0.14 -0.06 0.0" quat="1 0 1 0"/>
            <geom class="collision" size="0.034 0.015" pos="-0.24 -0.06 0.0" quat="1 0 0 0"/>
            <body name="right_link_4" pos="-0.245 -0.06 0" quat="1 0 0 0" gravcomp="1">
              <inertial pos="-0.0769778 -0.0527104 0.000154878" quat="0.667 0.667 -0.236 -0.236" mass="0.463511"
                diaginertia="0.000791532 0.000744733 0.000282116"/>
              <joint name="right_joint4" range="-1.5708 1.5708" class="dm4310"/>
              <geom class="visual" pos="0.00100023 0.164101 2.44738e-05" quat="1 1 1 -1" mesh="model2__10"/>
              <geom class="collision" size="0.03 0.015" pos="-0.073 -0.06 0.0" quat="1 1 0 0"/>
              <body name="right_link_5" pos="-0.074 -0.0395 2.5e-05" quat="1 -1 1 1" gravcomp="1">
                <inertial pos="3.64861e-05 0.00025665 0.0353526" quat="1 0 0 0" mass="0.350962"
                  diaginertia="0.000197802 0.0001775 0.000147402"/>
                <joint name="right_joint5" range="-1.5708 1.5708" class="dm4310"/>
                <geom class="visual" pos="0 -0.0749971 0.203601" quat="1.32679e-06 1 0 0" mesh="model2__11"/>
                <geom class="collision" size="0.030 0.015" pos="0 0.025 0.0395" quat="1 1 0 0"/>
                <body name="right_link_6" pos="0 0.0353 0.0395" quat="1 -1 0 0" gravcomp="1">
                  <inertial pos="-0.000217767 7.37059e-05 0.0270545" quat="1 1 0 0" mass="0.367476"
                    diaginertia="0.000265958 0.000242686 0.000227409"/>
                  <joint name="right_joint6" range="-2.0944 2.0944" class="dm4310"/>
                  <geom class="visual" pos="0 -0.164101 -0.110597" quat="1 -1 0 0" mesh="model2__12"/>
                  <geom class="visual" pos="0 -0.164101 -0.110597" quat="1 -1 0 0" mesh="model2__13"/>
                  <geom class="collision" size="0.01 0.035" pos="0 0.039 0.052" quat="1 0 1 0"/>
                  <geom class="collision" size="0.030 0.005" pos="0 0.0 0.03" quat="1 0 0 1"/>
                  <geom class="collision" size="0.01 0.035" pos="0 -0.039 0.052" quat="1 0 1 0"/>
                  <site name="right_tcp_site" pos="0 0 0" quat="1 0 0 -1" size="0.005" rgba="1 0 0 1" group="4"/>
                  <site name="right_grasp_site" pos="0 0 0.1347" quat="1 0 0 -1" size="0.005" rgba="0 1 0 1" group="4"/>
                  <body name="right_camera_d405" pos="-0.0107 0.095 0.062" quat="0.906 0.423 0 0">
                    <geom type="mesh" contype="0" conaffinity="0" group="3" density="0.001" mass="0.001"
                      rgba="0 0 0 0" mesh="camera_d405"/>
                    <geom name="right_cam_col" type="sphere" size="0.02" pos="0 0 0"
                      group="3" rgba="0 0 1 0.0" mass="0.001"/>
                    <body name="right_camera_frame" pos="0.009 0 0" quat="0 0 0 1">
                      <camera name="right" pos="0 0 0" quat="0 1 0 0" fovy="58"/>
                    </body>
                  </body>
                  <body name="right_link_left_finger" pos="-0.037 0.0392 0.0605" quat="1 0 1 0" gravcomp="1">
                    <inertial pos="-0.0192995 -0.0365902 0.039774" quat="0.757351 0.568898 -0.3199 0.0" mass="0.118"
                      diaginertia="0.000159084 0.000154909 4.63655e-05"/>
                    <joint class="finger" name="right_left_finger" range="-0.00205 0.0475"/>
                    <geom class="visual" pos="0.171097 -0.203301 0.037" quat="1 -1 -1 -1" mesh="model2__14"/>
                    <geom class="visual" pos="0.171097 -0.203301 0.037" quat="1 -1 -1 -1" mesh="model2__15"/>
                    <body name="right_lf_rot" quat="1 -1 -1 1" pos="0.0 -0.0392 0.037" gravcomp="1">
                      <geom class="collision" size="0.01 0.03" pos="0.0 -0.02 0.012" quat="1 0 1 0"
                        rgba="0.381493 0.492734 0.780446 1"/>
                      <geom class="collision" size="0.01 0.02" pos="-0.02 -0.01 0.032" quat="1 0 2.5 0"
                        rgba="0.381493 0.492734 0.780446 1"/>
                      <body name="right_lf_down" quat="1 0 0 0" pos="-0.044 0.0 0.0" gravcomp="1">
                        <geom class="collision" size="0.01 0.01" pos="0.0 -0.020 0.012" quat="1 -0.1 0 0"
                          rgba="0.381493 0.492734 0.780446 1"/>
                        <geom class="collision" size="0.003 0.022" pos="0.005 -0.014 0.04" quat="1 -0.2 0 0"
                          rgba="0.381493 0.492734 0.780446 1"/>
                        <geom class="collision" size="0.003 0.022" pos="-0.005 -0.014 0.04" quat="1 -0.2 0 0"
                          rgba="0.381493 0.492734 0.780446 1"/>
                        <geom class="collision" type="box" size="0.006 0.002 0.04" friction="3.0 0.1 0.01" priority="2" solref="0.004 1" solimp="0.998 0.998 0.001" pos="0 -0.0024 0.046" quat="1 0 0 0"
                          rgba="0.381493 0.492734 0.780446 1"/>
                        <geom class="collision" type="box" size="0.006 0.002 0.039" friction="3.0 0.1 0.01" priority="2" solref="0.004 1" solimp="0.998 0.998 0.001" pos="0.027 -0.0024 0.053"
                          quat="1 0 2.5 0" rgba="0.381493 0.492734 0.780446 1"/>
                        <geom class="sphere_collision" pos="0.003  -0.0004 0.078"/>
                        <geom class="sphere_collision" pos="-0.003 -0.0004 0.078"/>
                        <geom class="sphere_collision" pos="0.003  -0.0004 0.07"/>
                        <geom class="sphere_collision" pos="-0.003 -0.0004 0.07"/>
                        <geom class="sphere_collision" pos="0.003  -0.0004 0.06"/>
                        <geom class="sphere_collision" pos="-0.003 -0.0004 0.06"/>
                      </body>
                    </body>
                  </body>
                  <body name="right_link_right_finger" pos="0.037 -0.0392 0.0605" quat="1 0 1 0" gravcomp="1">
                    <inertial pos="-0.0192995 0.0365902 -0.039774" quat="-0.757351 0.568898 -0.3199 0" mass="0.118"
                      diaginertia="0.000159084 0.000154909 4.63655e-05"/>
                    <joint class="finger" name="right_right_finger" range="-0.0475 0.00205"/>
                    <geom class="visual" pos="0.171097 -0.124901 -0.037" quat="1 -1 -1 -1" mesh="model2__16"/>
                    <geom class="visual" pos="0.171097 -0.124901 -0.037" quat="1 -1 -1 -1" mesh="model2__17"/>
                    <body name="right_rf_rot" quat="1 1 -1 -1" pos="0.0 0.0392 -0.037" gravcomp="1">
                      <geom class="collision" size="0.01 0.03" pos="0.0 -0.02 0.012" quat="1 0 1 0"
                        rgba="0.381493 0.492734 0.780446 1"/>
                      <geom class="collision" size="0.01 0.02" pos="0.02 -0.01 0.032" quat="1 0 -2.5 0"
                        rgba="0.381493 0.492734 0.780446 1"/>
                      <body name="right_rf_down" quat="1 0 0 0" pos="0.044 0.0 0.0" gravcomp="1">
                        <geom class="collision" size="0.01 0.01" pos="0.0 -0.020 0.012" quat="1 -0.1 0 0"
                          rgba="0.381493 0.492734 0.780446 1"/>
                        <geom class="collision" size="0.003 0.022" pos="0.005 -0.014 0.04" quat="1 -0.2 0 0"
                          rgba="0.381493 0.492734 0.780446 1"/>
                        <geom class="collision" size="0.003 0.022" pos="-0.005 -0.014 0.04" quat="1 -0.2 0 0"
                          rgba="0.381493 0.492734 0.780446 1"/>
                        <geom class="collision" type="box" size="0.006 0.002 0.04" friction="3.0 0.1 0.01" priority="2" solref="0.004 1" solimp="0.998 0.998 0.001" pos="0 -0.0024 0.046" quat="1 0 0 0"
                          rgba="0.381493 0.492734 0.780446 1"/>
                        <geom class="collision" type="box" size="0.006 0.002 0.039" friction="3.0 0.1 0.01" priority="2" solref="0.004 1" solimp="0.998 0.998 0.001" pos="-0.027 -0.0024 0.053"
                          quat="1 0 -2.5 0" rgba="0.381493 0.492734 0.780446 1"/>
                        <geom class="sphere_collision" pos="0.003  -0.0004 0.078"/>
                        <geom class="sphere_collision" pos="-0.003 -0.0004 0.078"/>
                        <geom class="sphere_collision" pos="0.003  -0.0004 0.07"/>
                        <geom class="sphere_collision" pos="-0.003 -0.0004 0.07"/>
                        <geom class="sphere_collision" pos="0.003  -0.0004 0.06"/>
                        <geom class="sphere_collision" pos="-0.003 -0.0004 0.06"/>
                      </body>
                    </body>
                  </body>
                </body>
              </body>
            </body>
          </body>
        </body>
      </body>
    </body>
  </worldbody>

  <!-- Equality constraints: mirror left/right finger per arm -->
  <equality>
    <joint joint1="left_left_finger" joint2="left_right_finger" polycoef="0 -1 0 0 0"/>
    <joint joint1="right_left_finger" joint2="right_right_finger" polycoef="0 -1 0 0 0"/>
  </equality>

  <!-- Actuators: 14 total (7 per arm) -->
  <actuator>
    <!-- Left arm -->
    <position name="left_joint1" joint="left_joint1" class="dm4340"/>
    <position name="left_joint2" joint="left_joint2" class="dm4340"/>
    <position name="left_joint3" joint="left_joint3" class="dm4340"/>
    <position name="left_joint4" joint="left_joint4" class="dm4310" kp="20" kv=".5"/>
    <position name="left_joint5" joint="left_joint5" class="dm4310"/>
    <position name="left_joint6" joint="left_joint6" class="dm4310"/>
    <position class="finger" name="left_gripper" joint="left_left_finger"/>
    <!-- Right arm -->
    <position name="right_joint1" joint="right_joint1" class="dm4340"/>
    <position name="right_joint2" joint="right_joint2" class="dm4340"/>
    <position name="right_joint3" joint="right_joint3" class="dm4340"/>
    <position name="right_joint4" joint="right_joint4" class="dm4310" kp="20" kv=".5"/>
    <position name="right_joint5" joint="right_joint5" class="dm4310"/>
    <position name="right_joint6" joint="right_joint6" class="dm4310"/>
    <position class="finger" name="right_gripper" joint="right_left_finger"/>
  </actuator>

  <!-- Home keyframe -->
  <!-- qpos order: plate freejoint (7), then 16 arm joints -->
  <keyframe>
    <key name="home"
      qpos="0.50 0.20 0.76 1 0 0 0
            0 1.047 1.047 0 0 0 0 0  0 1.047 1.047 0 0 0 0 0"
      ctrl="0 1.047 1.047 0 0 0 0  0 1.047 1.047 0 0 0 0"/>
  </keyframe>
</mujoco>
